Workbook

Sheet Cal_NTC
A1: Parameters of NTC | F1: Point | G1: T_standard (Celsius) | H1: T_standard (K) | I1: V_o_Standard (V) | J1: R_NTC (Ohm) | K1: V_o_NTC_NonLinearization (V) | L1: R_eq (Ohm) | M1: R_eq_Sim (Ohm) | N1: V_o_NTC_Linearization (V) | O1: V_affter_NTC_Ideal (V) | P1: Error_V_o_NTC_Linear_ab (V) | Q1: Error_V_o_NTC_Linear_re (%) | R1: V_o_INA (V) | S1: V_o_INA_ideal (V) | T1: Error_V_o_INA_ab (V) | U1: Error_V_o_INA_re (%) | V1: V_o_ideal (V) | W1: V_o_Cal (V) | X1: Error_V_o_Cal_ab (V) | Y1: Error_V_o_Cal_re (%) | Z1: T_cal | AA1: Error_T_cal | AB1: V_o_Measurement (V) | AC1: Error_V_o_Measurement_ab (V) | AD1: Error_V_o_Measurement_re (%) | AE1: T_Measurement_Cal (Celsius) | AF1: Error_T_Measurement_Cal (%)
A2: Parameters | B2: Value | C2: Unit | F2: {=_xlfn.SEQUENCE(601,1,0,1)} -> 0 | G2: =F2*0.1+20 -> 20 | H2: =G2+273.15 -> 293.15 | I2: =ROUND(1/12*G2-5/3,6) -> 0 | J2: =ROUND(10000*EXP(($B$3)+($B$4/H2)+($B$5/(H2^2))+($B$6/(H2^3))),6) -> 12487.989 | K2: =$B$9*(2*$B$8+J2)-$B$9*$B$10 -> 11.507989 | L2: =ROUND(1/(1/(J2+2*$B$8)+1/($B$7)),6) -> 2220.6467 | M2: 2218.65 | N2: =$B$9*(L2+$B$10)*(L2/(L2+$B$10)) -> 2.2206467 | O2: =$B$11*G2+$B$12 -> 2.232 | P2: =ABS(N2-O2) -> 0.011353329 | Q2: =ABS(O2-N2)/O2 -> 0.0050866169 | R2: =ROUND(N2*$B$29,6)+RANDBETWEEN(-1,1)*$B$24+RANDBETWEEN(-1,1)*$B$25 -> 8.0999648 | S2: =O2*$B$23 -> 8.232 | T2: =ABS(R2-S2) -> 0.13203523 | U2: =ABS(S2-R2)/S2 -> 0.016039265 | V2: =$B$44*S2+$B$45 -> 0 | W2: =$B$46*R2+$B$47 -> -0.099964773 | X2: =ABS(V2-W2) -> 0.099964773 | Y2: =IF(V2 = 0, ABS(V2-W2)/(V2+0.0001), ABS(V2-W2)/V2) -> 999.64773 | Z2: =ROUND((W2+5/3)/(1/12),6) -> 18.800423 | AA2: =ABS(G2-Z2)/G2 -> 0.05997885
A3: A | B3: -14.6337 | C3: =SLOPE(N:N,G:G) -> -0.023478388 | F3: 1 | G3: =F3*0.1+20 -> 20.1 | H3: =G3+273.15 -> 293.25 | I3: =ROUND(1/12*G3-5/3,6) -> 0.008333 | J3: =ROUND(10000*EXP(($B$3)+($B$4/H3)+($B$5/(H3^2))+($B$6/(H3^3))),6) -> 12431.826 | K3: =$B$9*(2*$B$8+J3)-$B$9*$B$10 -> 11.451826 | L3: =ROUND(1/(1/(J3+2*$B$8)+1/($B$7)),6) -> 2218.8699 | M3: 2217.11 | N3: =$B$9*(L3+$B$10)*(L3/(L3+$B$10)) -> 2.2188699 | O3: =$B$11*G3+$B$12 -> 2.22971 | P3: =ABS(N3-O3) -> 0.010840139 | Q3: =ABS(O3-N3)/O3 -> 0.0048616811 | R3: =ROUND(N3*$B$29,6)+RANDBETWEEN(-1,1)*$B$24+RANDBETWEEN(-1,1)*$B$25 -> 8.0942545 | S3: =O3*$B$23 -> 8.2235541 | T3: =ABS(R3-S3) -> 0.12929958 | U3: =ABS(S3-R3)/S3 -> 0.015723078 | V3: =$B$44*S3+$B$45 -> 0.0083333333 | W3: =$B$46*R3+$B$47 -> -0.094254501 | X3: =ABS(V3-W3) -> 0.10258783 | Y3: =IF(V3 = 0, ABS(V3-W3)/(V3+0.0001), ABS(V3-W3)/V3) -> 12.31054 | Z3: =ROUND((W3+5/3)/(1/12),6) -> 18.868946 | AA3: =ABS(G3-Z3)/G3 -> 0.061246468
A4: B | B4: 4791.842 | C4: =INTERCEPT(N:N,G:G) -> 2.7207745 | F4: 2 | G4: =F4*0.1+20 -> 20.2 | H4: =G4+273.15 -> 293.35 | I4: =ROUND(1/12*G4-5/3,6) -> 0.016667 | J4: =ROUND(10000*EXP(($B$3)+($B$4/H4)+($B$5/(H4^2))+($B$6/(H4^3))),6) -> 12375.948 | K4: =$B$9*(2*$B$8+J4)-$B$9*$B$10 -> 11.395948 | L4: =ROUND(1/(1/(J4+2*$B$8)+1/($B$7)),6) -> 2217.089 | M4: 2215.56 | N4: =$B$9*(L4+$B$10)*(L4/(L4+$B$10)) -> 2.217089 | O4: =$B$11*G4+$B$12 -> 2.22742 | P4: =ABS(N4-O4) -> 0.010331036 | Q4: =ABS(O4-N4)/O4 -> 0.0046381176 | R4: =ROUND(N4*$B$29,6)+RANDBETWEEN(-1,1)*$B$24+RANDBETWEEN(-1,1)*$B$25 -> 8.0873731 | S4: =O4*$B$23 -> 8.2151082 | T4: =ABS(R4-S4) -> 0.12773504 | U4: =ABS(S4-R4)/S4 -> 0.015548795 | V4: =$B$44*S4+$B$45 -> 0.016666667 | W4: =$B$46*R4+$B$47 -> -0.087373137 | X4: =ABS(V4-W4) -> 0.1040398 | Y4: =IF(V4 = 0, ABS(V4-W4)/(V4+0.0001), ABS(V4-W4)/V4) -> 6.2423882 | Z4: =ROUND((W4+5/3)/(1/12),6) -> 18.951522 | AA4: =ABS(G4-Z4)/G4 -> 0.061805842
A5: C | B5: -115334 | F5: 3 | G5: =F5*0.1+20 -> 20.3 | H5: =G5+273.15 -> 293.45 | I5: =ROUND(1/12*G5-5/3,6) -> 0.025 | J5: =ROUND(10000*EXP(($B$3)+($B$4/H5)+($B$5/(H5^2))+($B$6/(H5^3))),6) -> 12320.355 | K5: =$B$9*(2*$B$8+J5)-$B$9*$B$10 -> 11.340355 | L5: =ROUND(1/(1/(J5+2*$B$8)+1/($B$7)),6) -> 2215.304 | M5: 2214 | N5: =$B$9*(L5+$B$10)*(L5/(L5+$B$10)) -> 2.215304 | O5: =$B$11*G5+$B$12 -> 2.22513 | P5: =ABS(N5-O5) -> 0.009826019 | Q5: =ABS(O5-N5)/O5 -> 0.0044159303 | R5: =ROUND(N5*$B$29,6)+RANDBETWEEN(-1,1)*$B$24+RANDBETWEEN(-1,1)*$B$25 -> 8.0804768 | S5: =O5*$B$23 -> 8.2066623 | T5: =ABS(R5-S5) -> 0.12618549 | U5: =ABS(S5-R5)/S5 -> 0.015375981 | V5: =$B$44*S5+$B$45 -> 0.025 | W5: =$B$46*R5+$B$47 -> -0.080476773 | X5: =ABS(V5-W5) -> 0.10547677 | Y5: =IF(V5 = 0, ABS(V5-W5)/(V5+0.0001), ABS(V5-W5)/V5) -> 4.2190709 | Z5: =ROUND((W5+5/3)/(1/12),6) -> 19.034279 | AA5: =ABS(G5-Z5)/G5 -> 0.062350788
A6: D | B6: -3730535 | F6: 4 | G6: =F6*0.1+20 -> 20.4 | H6: =G6+273.15 -> 293.55 | I6: =ROUND(1/12*G6-5/3,6) -> 0.033333 | J6: =ROUND(10000*EXP(($B$3)+($B$4/H6)+($B$5/(H6^2))+($B$6/(H6^3))),6) -> 12265.043 | K6: =$B$9*(2*$B$8+J6)-$B$9*$B$10 -> 11.285043 | L6: =ROUND(1/(1/(J6+2*$B$8)+1/($B$7)),6) -> 2213.5149 | M6: 2211.91 | N6: =$B$9*(L6+$B$10)*(L6/(L6+$B$10)) -> 2.2135149 | O6: =$B$11*G6+$B$12 -> 2.22284 | P6: =ABS(N6-O6) -> 0.009325082 | Q6: =ABS(O6-N6)/O6 -> 0.0041951207 | R6: =ROUND(N6*$B$29,6)+RANDBETWEEN(-1,1)*$B$24+RANDBETWEEN(-1,1)*$B$25 -> 8.0743361 | S6: =O6*$B$23 -> 8.1982163 | T6: =ABS(R6-S6) -> 0.12388021 | U6: =ABS(S6-R6)/S6 -> 0.015110629 | V6: =$B$44*S6+$B$45 -> 0.033333333 | W6: =$B$46*R6+$B$47 -> -0.074336137 | X6: =ABS(V6-W6) -> 0.10766947 | Y6: =IF(V6 = 0, ABS(V6-W6)/(V6+0.0001), ABS(V6-W6)/V6) -> 3.2300841 | Z6: =ROUND((W6+5/3)/(1/12),6) -> 19.107966 | AA6: =ABS(G6-Z6)/G6 -> 0.063335
A7: R_parallel | B7: =2700 -> 2700 | C7: Ohm | F7: 5 | G7: =F7*0.1+20 -> 20.5 | H7: =G7+273.15 -> 293.65 | I7: =ROUND(1/12*G7-5/3,6) -> 0.041667 | J7: =ROUND(10000*EXP(($B$3)+($B$4/H7)+($B$5/(H7^2))+($B$6/(H7^3))),6) -> 12210.013 | K7: =$B$9*(2*$B$8+J7)-$B$9*$B$10 -> 11.230013 | L7: =ROUND(1/(1/(J7+2*$B$8)+1/($B$7)),6) -> 2211.7218 | M7: 2210.34 | N7: =$B$9*(L7+$B$10)*(L7/(L7+$B$10)) -> 2.2117218 | O7: =$B$11*G7+$B$12 -> 2.22055 | P7: =ABS(N7-O7) -> 0.00882822 | Q7: =ABS(O7-N7)/O7 -> 0.0039756907 | R7: =ROUND(N7*$B$29,6)+RANDBETWEEN(-1,1)*$B$24+RANDBETWEEN(-1,1)*$B$25 -> 8.0681815 | S7: =O7*$B$23 -> 8.1897704 | T7: =ABS(R7-S7) -> 0.12158893 | U7: =ABS(S7-R7)/S7 -> 0.014846439 | V7: =$B$44*S7+$B$45 -> 0.041666667 | W7: =$B$46*R7+$B$47 -> -0.068181501 | X7: =ABS(V7-W7) -> 0.10984817 | Y7: =IF(V7 = 0, ABS(V7-W7)/(V7+0.0001), ABS(V7-W7)/V7) -> 2.636356 | Z7: =ROUND((W7+5/3)/(1/12),6) -> 19.181822 | AA7: =ABS(G7-Z7)/G7 -> 0.064301366
A8: R_wire | B8: 10 | C8: Ohm | F8: 6 | G8: =F8*0.1+20 -> 20.6 | H8: =G8+273.15 -> 293.75 | I8: =ROUND(1/12*G8-5/3,6) -> 0.05 | J8: =ROUND(10000*EXP(($B$3)+($B$4/H8)+($B$5/(H8^2))+($B$6/(H8^3))),6) -> 12155.261 | K8: =$B$9*(2*$B$8+J8)-$B$9*$B$10 -> 11.175261 | L8: =ROUND(1/(1/(J8+2*$B$8)+1/($B$7)),6) -> 2209.9246 | M8: 2208.5 | N8: =$B$9*(L8+$B$10)*(L8/(L8+$B$10)) -> 2.2099246 | O8: =$B$11*G8+$B$12 -> 2.21826 | P8: =ABS(N8-O8) -> 0.008335431 | Q8: =ABS(O8-N8)/O8 -> 0.0037576438 | R8: =ROUND(N8*$B$29,6)+RANDBETWEEN(-1,1)*$B$24+RANDBETWEEN(-1,1)*$B$25 -> 8.0604586 | S8: =O8*$B$23 -> 8.1813245 | T8: =ABS(R8-S8) -> 0.12086588 | U8: =ABS(S8-R8)/S8 -> 0.014773388 | V8: =$B$44*S8+$B$45 -> 0.05 | W8: =$B$46*R8+$B$47 -> -0.060458636 | X8: =ABS(V8-W8) -> 0.11045864 | Y8: =IF(V8 = 0, ABS(V8-W8)/(V8+0.0001), ABS(V8-W8)/V8) -> 2.2091727 | Z8: =ROUND((W8+5/3)/(1/12),6) -> 19.274496 | AA8: =ABS(G8-Z8)/G8 -> 0.064344854
A9: I_const | B9: =0.001 -> 0.001 | C9: A | F9: 7 | G9: =F9*0.1+20 -> 20.7 | H9: =G9+273.15 -> 293.85 | I9: =ROUND(1/12*G9-5/3,6) -> 0.058333 | J9: =ROUND(10000*EXP(($B$3)+($B$4/H9)+($B$5/(H9^2))+($B$6/(H9^3))),6) -> 12100.787 | K9: =$B$9*(2*$B$8+J9)-$B$9*$B$10 -> 11.120787 | L9: =ROUND(1/(1/(J9+2*$B$8)+1/($B$7)),6) -> 2208.1233 | M9: 2206.65 | N9: =$B$9*(L9+$B$10)*(L9/(L9+$B$10)) -> 2.2081233 | O9: =$B$11*G9+$B$12 -> 2.21597 | P9: =ABS(N9-O9) -> 0.00784671 | Q9: =ABS(O9-N9)/O9 -> 0.0035409821 | R9: =ROUND(N9*$B$29,6)+RANDBETWEEN(-1,1)*$B$24+RANDBETWEEN(-1,1)*$B$25 -> 8.0538779 | S9: =O9*$B$23 -> 8.1728786 | T9: =ABS(R9-S9) -> 0.11900074 | U9: =ABS(S9-R9)/S9 -> 0.014560444 | V9: =$B$44*S9+$B$45 -> 0.058333333 | W9: =$B$46*R9+$B$47 -> -0.053877863 | X9: =ABS(V9-W9) -> 0.1122112 | Y9: =IF(V9 = 0, ABS(V9-W9)/(V9+0.0001), ABS(V9-W9)/V9) -> 1.9236205 | Z9: =ROUND((W9+5/3)/(1/12),6) -> 19.353466 | AA9: =ABS(G9-Z9)/G9 -> 0.065049952
A10: R_offset | B10: 1000 | C10: Ohm | F10: 8 | G10: =F10*0.1+20 -> 20.8 | H10: =G10+273.15 -> 293.95 | I10: =ROUND(1/12*G10-5/3,6) -> 0.066667 | J10: =ROUND(10000*EXP(($B$3)+($B$4/H10)+($B$5/(H10^2))+($B$6/(H10^3))),6) -> 12046.589 | K10: =$B$9*(2*$B$8+J10)-$B$9*$B$10 -> 11.066589 | L10: =ROUND(1/(1/(J10+2*$B$8)+1/($B$7)),6) -> 2206.3179 | M10: 2204.53 | N10: =$B$9*(L10+$B$10)*(L10/(L10+$B$10)) -> 2.2063179 | O10: =$B$11*G10+$B$12 -> 2.21368 | P10: =ABS(N10-O10) -> 0.007362051 | Q10: =ABS(O10-N10)/O10 -> 0.003325707 | R10: =ROUND(N10*$B$29,6)+RANDBETWEEN(-1,1)*$B$24+RANDBETWEEN(-1,1)*$B$25 -> 8.0473036 | S10: =O10*$B$23 -> 8.1644327 | T10: =ABS(R10-S10) -> 0.11712905 | U10: =ABS(S10-R10)/S10 -> 0.014346257 | V10: =$B$44*S10+$B$45 -> 0.066666667 | W10: =$B$46*R10+$B$47 -> -0.047303636 | X10: =ABS(V10-W10) -> 0.1139703 | Y10: =IF(V10 = 0, ABS(V10-W10)/(V10+0.0001), ABS(V10-W10)/V10) -> 1.7095545 | Z10: =ROUND((W10+5/3)/(1/12),6) -> 19.432356 | AA10: =ABS(G10-Z10)/G10 -> 0.065752115
A11: A_V_o_NTC_Linear | B11: -0.0229 | C11: Num | F11: 9 | G11: =F11*0.1+20 -> 20.9 | H11: =G11+273.15 -> 294.05 | I11: =ROUND(1/12*G11-5/3,6) -> 0.075 | J11: =ROUND(10000*EXP(($B$3)+($B$4/H11)+($B$5/(H11^2))+($B$6/(H11^3))),6) -> 11992.666 | K11: =$B$9*(2*$B$8+J11)-$B$9*$B$10 -> 11.012666 | L11: =ROUND(1/(1/(J11+2*$B$8)+1/($B$7)),6) -> 2204.5085 | M11: 2202.93 | N11: =$B$9*(L11+$B$10)*(L11/(L11+$B$10)) -> 2.2045085 | O11: =$B$11*G11+$B$12 -> 2.21139 | P11: =ABS(N11-O11) -> 0.006881451 | Q11: =ABS(O11-N11)/O11 -> 0.0031118215 | R11: =ROUND(N11*$B$29,6)+RANDBETWEEN(-1,1)*$B$24+RANDBETWEEN(-1,1)*$B$25 -> 8.0418705 | S11: =O11*$B$23 -> 8.1559868 | T11: =ABS(R11-S11) -> 0.11411627 | U11: =ABS(S11-R11)/S11 -> 0.013991719 | V11: =$B$44*S11+$B$45 -> 0.075 | W11: =$B$46*R11+$B$47 -> -0.041870501 | X11: =ABS(V11-W11) -> 0.1168705 | Y11: =IF(V11 = 0, ABS(V11-W11)/(V11+0.0001), ABS(V11-W11)/V11) -> 1.5582734 | Z11: =ROUND((W11+5/3)/(1/12),6) -> 19.497554 | AA11: =ABS(G11-Z11)/G11 -> 0.067102679
A12: B_V_o_NTC_Linear | B12: 2.69 | C12: Num | F12: 10 | G12: =F12*0.1+20 -> 21 | H12: =G12+273.15 -> 294.15 | I12: =ROUND(1/12*G12-5/3,6) -> 0.083333 | J12: =ROUND(10000*EXP(($B$3)+($B$4/H12)+($B$5/(H12^2))+($B$6/(H12^3))),6) -> 11939.015 | K12: =$B$9*(2*$B$8+J12)-$B$9*$B$10 -> 10.959015 | L12: =ROUND(1/(1/(J12+2*$B$8)+1/($B$7)),6) -> 2202.6951 | M12: 2201.06 | N12: =$B$9*(L12+$B$10)*(L12/(L12+$B$10)) -> 2.2026951 | O12: =$B$11*G12+$B$12 -> 2.2091 | P12: =ABS(N12-O12) -> 0.006404905 | Q12: =ABS(O12-N12)/O12 -> 0.0028993278 | R12: =ROUND(N12*$B$29,6)+RANDBETWEEN(-1,1)*$B$24+RANDBETWEEN(-1,1)*$B$25 -> 8.0336925 | S12: =O12*$B$23 -> 8.1475409 | T12: =ABS(R12-S12) -> 0.11384836 | U12: =ABS(S12-R12)/S12 -> 0.01397334 | V12: =$B$44*S12+$B$45 -> 0.083333333 | W12: =$B$46*R12+$B$47 -> -0.033692499 | X12: =ABS(V12-W12) -> 0.11702583 | Y12: =IF(V12 = 0, ABS(V12-W12)/(V12+0.0001), ABS(V12-W12)/V12) -> 1.40431 | Z12: =ROUND((W12+5/3)/(1/12),6) -> 19.59569 | AA12: =ABS(G12-Z12)/G12 -> 0.066871905
A13: MAX_V_affter_NTC_ideal | B13: =MAX(O:O) -> 2.232 | C13: V | F13: 11 | G13: =F13*0.1+20 -> 21.1 | H13: =G13+273.15 -> 294.25 | I13: =ROUND(1/12*G13-5/3,6) -> 0.091667 | J13: =ROUND(10000*EXP(($B$3)+($B$4/H13)+($B$5/(H13^2))+($B$6/(H13^3))),6) -> 11885.636 | K13: =$B$9*(2*$B$8+J13)-$B$9*$B$10 -> 10.905636 | L13: =ROUND(1/(1/(J13+2*$B$8)+1/($B$7)),6) -> 2200.8776 | M13: 2199.44 | N13: =$B$9*(L13+$B$10)*(L13/(L13+$B$10)) -> 2.2008776 | O13: =$B$11*G13+$B$12 -> 2.20681 | P13: =ABS(N13-O13) -> 0.005932408 | Q13: =ABS(O13-N13)/O13 -> 0.0026882278 | R13: =ROUND(N13*$B$29,6)+RANDBETWEEN(-1,1)*$B$24+RANDBETWEEN(-1,1)*$B$25 -> 8.0282304 | S13: =O13*$B$23 -> 8.1390949 | T13: =ABS(R13-S13) -> 0.11086458 | U13: =ABS(S13-R13)/S13 -> 0.013621242 | V13: =$B$44*S13+$B$45 -> 0.091666667 | W13: =$B$46*R13+$B$47 -> -0.028230364 | X13: =ABS(V13-W13) -> 0.11989703 | Y13: =IF(V13 = 0, ABS(V13-W13)/(V13+0.0001), ABS(V13-W13)/V13) -> 1.3079676 | Z13: =ROUND((W13+5/3)/(1/12),6) -> 19.661236 | AA13: =ABS(G13-Z13)/G13 -> 0.068187867
A14: MIN_V_affter_NTC_ideal | B14: =MIN(O:O) -> 0.858 | C14: V | F14: 12 | G14: =F14*0.1+20 -> 21.2 | H14: =G14+273.15 -> 294.35 | I14: =ROUND(1/12*G14-5/3,6) -> 0.1 | J14: =ROUND(10000*EXP(($B$3)+($B$4/H14)+($B$5/(H14^2))+($B$6/(H14^3))),6) -> 11832.526 | K14: =$B$9*(2*$B$8+J14)-$B$9*$B$10 -> 10.852526 | L14: =ROUND(1/(1/(J14+2*$B$8)+1/($B$7)),6) -> 2199.056 | M14: 2197.56 | N14: =$B$9*(L14+$B$10)*(L14/(L14+$B$10)) -> 2.199056 | O14: =$B$11*G14+$B$12 -> 2.20452 | P14: =ABS(N14-O14) -> 0.005463956 | Q14: =ABS(O14-N14)/O14 -> 0.0024785241 | R14: =ROUND(N14*$B$29,6)+RANDBETWEEN(-1,1)*$B$24+RANDBETWEEN(-1,1)*$B$25 -> 8.0215854 | S14: =O14*$B$23 -> 8.130649 | T14: =ABS(R14-S14) -> 0.10906367 | U14: =ABS(S14-R14)/S14 -> 0.013413894 | V14: =$B$44*S14+$B$45 -> 0.1 | W14: =$B$46*R14+$B$47 -> -0.021585364 | X14: =ABS(V14-W14) -> 0.12158536 | Y14: =IF(V14 = 0, ABS(V14-W14)/(V14+0.0001), ABS(V14-W14)/V14) -> 1.2158536 | Z14: =ROUND((W14+5/3)/(1/12),6) -> 19.740976 | AA14: =ABS(G14-Z14)/G14 -> 0.068821887
A15: MAX_Error_V_o_NTC_Linear_ab | B15: =MAX(P:P) -> 0.023820459 | C15: V | F15: 13 | G15: =F15*0.1+20 -> 21.3 | H15: =G15+273.15 -> 294.45 | I15: =ROUND(1/12*G15-5/3,6) -> 0.108333 | J15: =ROUND(10000*EXP(($B$3)+($B$4/H15)+($B$5/(H15^2))+($B$6/(H15^3))),6) -> 11779.685 | K15: =$B$9*(2*$B$8+J15)-$B$9*$B$10 -> 10.799685 | L15: =ROUND(1/(1/(J15+2*$B$8)+1/($B$7)),6) -> 2197.2305 | M15: 2195.93 | N15: =$B$9*(L15+$B$10)*(L15/(L15+$B$10)) -> 2.1972305 | O15: =$B$11*G15+$B$12 -> 2.20223 | P15: =ABS(N15-O15) -> 0.004999544 | Q15: =ABS(O15-N15)/O15 -> 0.0022702188 | R15: =ROUND(N15*$B$29,6)+RANDBETWEEN(-1,1)*$B$24+RANDBETWEEN(-1,1)*$B$25 -> 8.0149264 | S15: =O15*$B$23 -> 8.1222031 | T15: =ABS(R15-S15) -> 0.10727675 | U15: =ABS(S15-R15)/S15 -> 0.013207839 | V15: =$B$44*S15+$B$45 -> 0.10833333 | W15: =$B$46*R15+$B$47 -> -0.014926364 | X15: =ABS(V15-W15) -> 0.1232597 | Y15: =IF(V15 = 0, ABS(V15-W15)/(V15+0.0001), ABS(V15-W15)/V15) -> 1.1377818 | Z15: =ROUND((W15+5/3)/(1/12),6) -> 19.820884 | AA15: =ABS(G15-Z15)/G15 -> 0.069442066
A16: MIN_Error_V_o_NTC_Linear_ab | B16: =MIN(P:P) -> 4.81e-06 | C16: V | F16: 14 | G16: =F16*0.1+20 -> 21.4 | H16: =G16+273.15 -> 294.55 | I16: =ROUND(1/12*G16-5/3,6) -> 0.116667 | J16: =ROUND(10000*EXP(($B$3)+($B$4/H16)+($B$5/(H16^2))+($B$6/(H16^3))),6) -> 11727.111 | K16: =$B$9*(2*$B$8+J16)-$B$9*$B$10 -> 10.747111 | L16: =ROUND(1/(1/(J16+2*$B$8)+1/($B$7)),6) -> 2195.4008 | M16: 2193.76 | N16: =$B$9*(L16+$B$10)*(L16/(L16+$B$10)) -> 2.1954008 | O16: =$B$11*G16+$B$12 -> 2.19994 | P16: =ABS(N16-O16) -> 0.004539166 | Q16: =ABS(O16-N16)/O16 -> 0.0020633135 | R16: =ROUND(N16*$B$29,6)+RANDBETWEEN(-1,1)*$B$24+RANDBETWEEN(-1,1)*$B$25 -> 8.007868 | S16: =O16*$B$23 -> 8.1137572 | T16: =ABS(R16-S16) -> 0.1058892 | U16: =ABS(S16-R16)/S16 -> 0.013050576 | V16: =$B$44*S16+$B$45 -> 0.11666667 | W16: =$B$46*R16+$B$47 -> -0.007868 | X16: =ABS(V16-W16) -> 0.12453467 | Y16: =IF(V16 = 0, ABS(V16-W16)/(V16+0.0001), ABS(V16-W16)/V16) -> 1.06744 | Z16: =ROUND((W16+5/3)/(1/12),6) -> 19.905584 | AA16: =ABS(G16-Z16)/G16 -> 0.069832523
A17: MAX_ERror_V_o_NTC_Linear_re | B17: =MAX(Q:Q) -> 0.016244587 | C17: % | F17: 15 | G17: =F17*0.1+20 -> 21.5 | H17: =G17+273.15 -> 294.65 | I17: =ROUND(1/12*G17-5/3,6) -> 0.125 | J17: =ROUND(10000*EXP(($B$3)+($B$4/H17)+($B$5/(H17^2))+($B$6/(H17^3))),6) -> 11674.802 | K17: =$B$9*(2*$B$8+J17)-$B$9*$B$10 -> 10.694802 | L17: =ROUND(1/(1/(J17+2*$B$8)+1/($B$7)),6) -> 2193.5672 | M17: 2191.86 | N17: =$B$9*(L17+$B$10)*(L17/(L17+$B$10)) -> 2.1935672 | O17: =$B$11*G17+$B$12 -> 2.19765 | P17: =ABS(N17-O17) -> 0.004082818 | Q17: =ABS(O17-N17)/O17 -> 0.0018578108 | R17: =ROUND(N17*$B$29,6)+RANDBETWEEN(-1,1)*$B$24+RANDBETWEEN(-1,1)*$B$25 -> 8.0007829 | S17: =O17*$B$23 -> 8.1053113 | T17: =ABS(R17-S17) -> 0.10452843 | U17: =ABS(S17-R17)/S17 -> 0.012896288 | V17: =$B$44*S17+$B$45 -> 0.125 | W17: =$B$46*R17+$B$47 -> -0.00078286297 | X17: =ABS(V17-W17) -> 0.12578286 | Y17: =IF(V17 = 0, ABS(V17-W17)/(V17+0.0001), ABS(V17-W17)/V17) -> 1.0062629 | Z17: =ROUND((W17+5/3)/(1/12),6) -> 19.990606 | AA17: =ABS(G17-Z17)/G17 -> 0.070204372
A18: MIN_ERror_V_o_NTC_Linear_re | B18: =MIN(Q:Q) -> 3.1696452e-06 | C18: % | F18: 16 | G18: =F18*0.1+20 -> 21.6 | H18: =G18+273.15 -> 294.75 | I18: =ROUND(1/12*G18-5/3,6) -> 0.133333 | J18: =ROUND(10000*EXP(($B$3)+($B$4/H18)+($B$5/(H18^2))+($B$6/(H18^3))),6) -> 11622.757 | K18: =$B$9*(2*$B$8+J18)-$B$9*$B$10 -> 10.642757 | L18: =ROUND(1/(1/(J18+2*$B$8)+1/($B$7)),6) -> 2191.7295 | M18: 2189.94 | N18: =$B$9*(L18+$B$10)*(L18/(L18+$B$10)) -> 2.1917295 | O18: =$B$11*G18+$B$12 -> 2.19536 | P18: =ABS(N18-O18) -> 0.003630494 | Q18: =ABS(O18-N18)/O18 -> 0.0016537124 | R18: =ROUND(N18*$B$29,6)+RANDBETWEEN(-1,1)*$B$24+RANDBETWEEN(-1,1)*$B$25 -> 7.9944652 | S18: =O18*$B$23 -> 8.0968654 | T18: =ABS(R18-S18) -> 0.10240015 | U18: =ABS(S18-R18)/S18 -> 0.012646888 | V18: =$B$44*S18+$B$45 -> 0.13333333 | W18: =$B$46*R18+$B$47 -> 0.0055347726 | X18: =ABS(V18-W18) -> 0.12779856 | Y18: =IF(V18 = 0, ABS(V18-W18)/(V18+0.0001), ABS(V18-W18)/V18) -> 0.95848921 | Z18: =ROUND((W18+5/3)/(1/12),6) -> 20.066417 | AA18: =ABS(G18-Z18)/G18 -> 0.070999213
F19: 17 | G19: =F19*0.1+20 -> 21.7 | H19: =G19+273.15 -> 294.85 | I19: =ROUND(1/12*G19-5/3,6) -> 0.141667 | J19: =ROUND(10000*EXP(($B$3)+($B$4/H19)+($B$5/(H19^2))+($B$6/(H19^3))),6) -> 11570.974 | K19: =$B$9*(2*$B$8+J19)-$B$9*$B$10 -> 10.590974 | L19: =ROUND(1/(1/(J19+2*$B$8)+1/($B$7)),6) -> 2189.8878 | M19: 2188.28 | N19: =$B$9*(L19+$B$10)*(L19/(L19+$B$10)) -> 2.1898878 | O19: =$B$11*G19+$B$12 -> 2.19307 | P19: =ABS(N19-O19) -> 0.00318219 | Q19: =ABS(O19-N19)/O19 -> 0.0014510207 | R19: =ROUND(N19*$B$29,6)+RANDBETWEEN(-1,1)*$B$24+RANDBETWEEN(-1,1)*$B$25 -> 7.9873629 | S19: =O19*$B$23 -> 8.0884195 | T19: =ABS(R19-S19) -> 0.1010566 | U19: =ABS(S19-R19)/S19 -> 0.012493986 | V19: =$B$44*S19+$B$45 -> 0.14166667 | W19: =$B$46*R19+$B$47 -> 0.012637137 | X19: =ABS(V19-W19) -> 0.12902953 | Y19: =IF(V19 = 0, ABS(V19-W19)/(V19+0.0001), ABS(V19-W19)/V19) -> 0.91079668 | Z19: =ROUND((W19+5/3)/(1/12),6) -> 20.151646 | AA19: =ABS(G19-Z19)/G19 -> 0.071352719
A20: INA128PA | F20: 18 | G20: =F20*0.1+20 -> 21.8 | H20: =G20+273.15 -> 294.95 | I20: =ROUND(1/12*G20-5/3,6) -> 0.15 | J20: =ROUND(10000*EXP(($B$3)+($B$4/H20)+($B$5/(H20^2))+($B$6/(H20^3))),6) -> 11519.452 | K20: =$B$9*(2*$B$8+J20)-$B$9*$B$10 -> 10.539452 | L20: =ROUND(1/(1/(J20+2*$B$8)+1/($B$7)),6) -> 2188.0421 | M20: 2186.35 | N20: =$B$9*(L20+$B$10)*(L20/(L20+$B$10)) -> 2.1880421 | O20: =$B$11*G20+$B$12 -> 2.19078 | P20: =ABS(N20-O20) -> 0.0027379 | Q20: =ABS(O20-N20)/O20 -> 0.0012497375 | R20: =ROUND(N20*$B$29,6)+RANDBETWEEN(-1,1)*$B$24+RANDBETWEEN(-1,1)*$B$25 -> 7.9814114 | S20: =O20*$B$23 -> 8.0799735 | T20: =ABS(R20-S20) -> 0.098562184 | U20: =ABS(S20-R20)/S20 -> 0.01219833 | V20: =$B$44*S20+$B$45 -> 0.15 | W20: =$B$46*R20+$B$47 -> 0.018588636 | X20: =ABS(V20-W20) -> 0.13141136 | Y20: =IF(V20 = 0, ABS(V20-W20)/(V20+0.0001), ABS(V20-W20)/V20) -> 0.87607576 | Z20: =ROUND((W20+5/3)/(1/12),6) -> 20.223064 | AA20: =ABS(G20-Z20)/G20 -> 0.072336514
A21: Parameters | B21: Value | C21: Unit | F21: 19 | G21: =F21*0.1+20 -> 21.9 | H21: =G21+273.15 -> 295.05 | I21: =ROUND(1/12*G21-5/3,6) -> 0.158333 | J21: =ROUND(10000*EXP(($B$3)+($B$4/H21)+($B$5/(H21^2))+($B$6/(H21^3))),6) -> 11468.19 | K21: =$B$9*(2*$B$8+J21)-$B$9*$B$10 -> 10.48819 | L21: =ROUND(1/(1/(J21+2*$B$8)+1/($B$7)),6) -> 2186.1924 | M21: 2184.67 | N21: =$B$9*(L21+$B$10)*(L21/(L21+$B$10)) -> 2.1861924 | O21: =$B$11*G21+$B$12 -> 2.18849 | P21: =ABS(N21-O21) -> 0.002297619 | Q21: =ABS(O21-N21)/O21 -> 0.001049865 | R21: =ROUND(N21*$B$29,6)+RANDBETWEEN(-1,1)*$B$24+RANDBETWEEN(-1,1)*$B$25 -> 7.9746644 | S21: =O21*$B$23 -> 8.0715276 | T21: =ABS(R21-S21) -> 0.09686327 | U21: =ABS(S21-R21)/S21 -> 0.012000612 | V21: =$B$44*S21+$B$45 -> 0.15833333 | W21: =$B$46*R21+$B$47 -> 0.025335636 | X21: =ABS(V21-W21) -> 0.1329977 | Y21: =IF(V21 = 0, ABS(V21-W21)/(V21+0.0001), ABS(V21-W21)/V21) -> 0.83998546 | Z21: =ROUND((W21+5/3)/(1/12),6) -> 20.304028 | AA21: =ABS(G21-Z21)/G21 -> 0.072875434
A22: R_G | B22: =18600 -> 18600 | C22: Ohm | F22: 20 | G22: =F22*0.1+20 -> 22 | H22: =G22+273.15 -> 295.15 | I22: =ROUND(1/12*G22-5/3,6) -> 0.166667 | J22: =ROUND(10000*EXP(($B$3)+($B$4/H22)+($B$5/(H22^2))+($B$6/(H22^3))),6) -> 11417.185 | K22: =$B$9*(2*$B$8+J22)-$B$9*$B$10 -> 10.437185 | L22: =ROUND(1/(1/(J22+2*$B$8)+1/($B$7)),6) -> 2184.3387 | M22: 2182.73 | N22: =$B$9*(L22+$B$10)*(L22/(L22+$B$10)) -> 2.1843387 | O22: =$B$11*G22+$B$12 -> 2.1862 | P22: =ABS(N22-O22) -> 0.001861342 | Q22: =ABS(O22-N22)/O22 -> 0.00085140518 | R22: =ROUND(N22*$B$29,6)+RANDBETWEEN(-1,1)*$B$24+RANDBETWEEN(-1,1)*$B$25 -> 7.9675072 | S22: =O22*$B$23 -> 8.0630817 | T22: =ABS(R22-S22) -> 0.095574493 | U22: =ABS(S22-R22)/S22 -> 0.011853345 | V22: =$B$44*S22+$B$45 -> 0.16666667 | W22: =$B$46*R22+$B$47 -> 0.032492773 | X22: =ABS(V22-W22) -> 0.13417389 | Y22: =IF(V22 = 0, ABS(V22-W22)/(V22+0.0001), ABS(V22-W22)/V22) -> 0.80504336 | Z22: =ROUND((W22+5/3)/(1/12),6) -> 20.389913 | AA22: =ABS(G22-Z22)/G22 -> 0.073185773
A23: G_INA | B23: =1+(50000/$B$22) -> 3.688172 | C23: Lần | F23: 21 | G23: =F23*0.1+20 -> 22.1 | H23: =G23+273.15 -> 295.25 | I23: =ROUND(1/12*G23-5/3,6) -> 0.175 | J23: =ROUND(10000*EXP(($B$3)+($B$4/H23)+($B$5/(H23^2))+($B$6/(H23^3))),6) -> 11366.438 | K23: =$B$9*(2*$B$8+J23)-$B$9*$B$10 -> 10.386438 | L23: =ROUND(1/(1/(J23+2*$B$8)+1/($B$7)),6) -> 2182.4809 | M23: 2181.04 | N23: =$B$9*(L23+$B$10)*(L23/(L23+$B$10)) -> 2.1824809 | O23: =$B$11*G23+$B$12 -> 2.18391 | P23: =ABS(N23-O23) -> 0.001429062 | Q23: =ABS(O23-N23)/O23 -> 0.00065435938 | R23: =ROUND(N23*$B$29,6)+RANDBETWEEN(-1,1)*$B$24+RANDBETWEEN(-1,1)*$B$25 -> 7.9603459 | S23: =O23*$B$23 -> 8.0546358 | T23: =ABS(R23-S23) -> 0.094289943 | U23: =ABS(S23-R23)/S23 -> 0.011706295 | V23: =$B$44*S23+$B$45 -> 0.175 | W23: =$B$46*R23+$B$47 -> 0.039654137 | X23: =ABS(V23-W23) -> 0.13534586 | Y23: =IF(V23 = 0, ABS(V23-W23)/(V23+0.0001), ABS(V23-W23)/V23) -> 0.77340493 | Z23: =ROUND((W23+5/3)/(1/12),6) -> 20.47585 | AA23: =ABS(G23-Z23)/G23 -> 0.07349095
A24: Offset_Vol | B24: =(125+1000/$B$23)*10^-6 -> 0.00039613703 | C24: V | F24: 22 | G24: =F24*0.1+20 -> 22.2 | H24: =G24+273.15 -> 295.35 | I24: =ROUND(1/12*G24-5/3,6) -> 0.183333 | J24: =ROUND(10000*EXP(($B$3)+($B$4/H24)+($B$5/(H24^2))+($B$6/(H24^3))),6) -> 11315.945 | K24: =$B$9*(2*$B$8+J24)-$B$9*$B$10 -> 10.335945 | L24: =ROUND(1/(1/(J24+2*$B$8)+1/($B$7)),6) -> 2180.6192 | M24: 2178.56 | N24: =$B$9*(L24+$B$10)*(L24/(L24+$B$10)) -> 2.1806192 | O24: =$B$11*G24+$B$12 -> 2.18162 | P24: =ABS(N24-O24) -> 0.001000775 | Q24: =ABS(O24-N24)/O24 -> 0.00045873021 | R24: =ROUND(N24*$B$29,6)+RANDBETWEEN(-1,1)*$B$24+RANDBETWEEN(-1,1)*$B$25 -> 7.9535549 | S24: =O24*$B$23 -> 8.0461899 | T24: =ABS(R24-S24) -> 0.092635029 | U24: =ABS(S24-R24)/S24 -> 0.011512906 | V24: =$B$44*S24+$B$45 -> 0.18333333 | W24: =$B$46*R24+$B$47 -> 0.046445137 | X24: =ABS(V24-W24) -> 0.1368882 | Y24: =IF(V24 = 0, ABS(V24-W24)/(V24+0.0001), ABS(V24-W24)/V24) -> 0.74666289 | Z24: =ROUND((W24+5/3)/(1/12),6) -> 20.557342 | AA24: =ABS(G24-Z24)/G24 -> 0.073993604
A25: Offset_Vol_T | B25: =(1+20/$B$23)*10^-6 * (MAX(G:G)-MIN(G:G)) -> 0.00038536443 | C25: V | F25: 23 | G25: =F25*0.1+20 -> 22.3 | H25: =G25+273.15 -> 295.45 | I25: =ROUND(1/12*G25-5/3,6) -> 0.191667 | J25: =ROUND(10000*EXP(($B$3)+($B$4/H25)+($B$5/(H25^2))+($B$6/(H25^3))),6) -> 11265.706 | K25: =$B$9*(2*$B$8+J25)-$B$9*$B$10 -> 10.285706 | L25: =ROUND(1/(1/(J25+2*$B$8)+1/($B$7)),6) -> 2178.7535 | M25: 2177.37 | N25: =$B$9*(L25+$B$10)*(L25/(L25+$B$10)) -> 2.1787535 | O25: =$B$11*G25+$B$12 -> 2.17933 | P25: =ABS(N25-O25) -> 0.000576475 | Q25: =ABS(O25-N25)/O25 -> 0.00026451937 | R25: =ROUND(N25*$B$29,6)+RANDBETWEEN(-1,1)*$B$24+RANDBETWEEN(-1,1)*$B$25 -> 7.9471568 | S25: =O25*$B$23 -> 8.037744 | T25: =ABS(R25-S25) -> 0.090587206 | U25: =ABS(S25-R25)/S25 -> 0.011270228 | V25: =$B$44*S25+$B$45 -> 0.19166667 | W25: =$B$46*R25+$B$47 -> 0.052843227 | X25: =ABS(V25-W25) -> 0.13882344 | Y25: =IF(V25 = 0, ABS(V25-W25)/(V25+0.0001), ABS(V25-W25)/V25) -> 0.7242962 | Z25: =ROUND((W25+5/3)/(1/12),6) -> 20.634119 | AA25: =ABS(G25-Z25)/G25 -> 0.074703184
A26: Gain_Error | B26: =0.5% -> 0.005 | C26: =SUM(B26:B28) -> 0.01101 | F26: 24 | G26: =F26*0.1+20 -> 22.4 | H26: =G26+273.15 -> 295.55 | I26: =ROUND(1/12*G26-5/3,6) -> 0.2 | J26: =ROUND(10000*EXP(($B$3)+($B$4/H26)+($B$5/(H26^2))+($B$6/(H26^3))),6) -> 11215.719 | K26: =$B$9*(2*$B$8+J26)-$B$9*$B$10 -> 10.235719 | L26: =ROUND(1/(1/(J26+2*$B$8)+1/($B$7)),6) -> 2176.8838 | M26: 2174.88 | N26: =$B$9*(L26+$B$10)*(L26/(L26+$B$10)) -> 2.1768838 | O26: =$B$11*G26+$B$12 -> 2.17704 | P26: =ABS(N26-O26) -> 0.000156155 | Q26: =ABS(O26-N26)/O26 -> 7.1728126e-05 | R26: =ROUND(N26*$B$29,6)+RANDBETWEEN(-1,1)*$B$24+RANDBETWEEN(-1,1)*$B$25 -> 7.9403152 | S26: =O26*$B$23 -> 8.0292981 | T26: =ABS(R26-S26) -> 0.088982837 | U26: =ABS(S26-R26)/S26 -> 0.011082269 | V26: =$B$44*S26+$B$45 -> 0.2 | W26: =$B$46*R26+$B$47 -> 0.059684773 | X26: =ABS(V26-W26) -> 0.14031523 | Y26: =IF(V26 = 0, ABS(V26-W26)/(V26+0.0001), ABS(V26-W26)/V26) -> 0.70157614 | Z26: =ROUND((W26+5/3)/(1/12),6) -> 20.716217 | AA26: =ABS(G26-Z26)/G26 -> 0.075168884
A27: Gain_Drift | B27: =(100/10000)% * (MAX(G:G)-MIN(G:G)) -> 0.006 | F27: 25 | G27: =F27*0.1+20 -> 22.5 | H27: =G27+273.15 -> 295.65 | I27: =ROUND(1/12*G27-5/3,6) -> 0.208333 | J27: =ROUND(10000*EXP(($B$3)+($B$4/H27)+($B$5/(H27^2))+($B$6/(H27^3))),6) -> 11165.984 | K27: =$B$9*(2*$B$8+J27)-$B$9*$B$10 -> 10.185984 | L27: =ROUND(1/(1/(J27+2*$B$8)+1/($B$7)),6) -> 2175.0102 | M27: 2173.16 | N27: =$B$9*(L27+$B$10)*(L27/(L27+$B$10)) -> 2.1750102 | O27: =$B$11*G27+$B$12 -> 2.17475 | P27: =ABS(N27-O27) -> 0.000260189 | Q27: =ABS(O27-N27)/O27 -> 0.00011964088 | R27: =ROUND(N27*$B$29,6)+RANDBETWEEN(-1,1)*$B$24+RANDBETWEEN(-1,1)*$B$25 -> 7.9334812 | S27: =O27*$B$23 -> 8.0208522 | T27: =ABS(R27-S27) -> 0.087370923 | U27: =ABS(S27-R27)/S27 -> 0.010892973 | V27: =$B$44*S27+$B$45 -> 0.20833333 | W27: =$B$46*R27+$B$47 -> 0.066518773 | X27: =ABS(V27-W27) -> 0.14181456 | Y27: =IF(V27 = 0, ABS(V27-W27)/(V27+0.0001), ABS(V27-W27)/V27) -> 0.68070989 | Z27: =ROUND((W27+5/3)/(1/12),6) -> 20.798225 | AA27: =ABS(G27-Z27)/G27 -> 0.075634444
A28: Gain_Nonlinearity | B28: 1e-05 | F28: 26 | G28: =F28*0.1+20 -> 22.6 | H28: =G28+273.15 -> 295.75 | I28: =ROUND(1/12*G28-5/3,6) -> 0.216667 | J28: =ROUND(10000*EXP(($B$3)+($B$4/H28)+($B$5/(H28^2))+($B$6/(H28^3))),6) -> 11116.498 | K28: =$B$9*(2*$B$8+J28)-$B$9*$B$10 -> 10.136498 | L28: =ROUND(1/(1/(J28+2*$B$8)+1/($B$7)),6) -> 2173.1326 | M28: 2171.17 | N28: =$B$9*(L28+$B$10)*(L28/(L28+$B$10)) -> 2.1731326 | O28: =$B$11*G28+$B$12 -> 2.17246 | P28: =ABS(N28-O28) -> 0.000672565 | Q28: =ABS(O28-N28)/O28 -> 0.00030958683 | R28: =ROUND(N28*$B$29,6)+RANDBETWEEN(-1,1)*$B$24+RANDBETWEEN(-1,1)*$B$25 -> 7.9274245 | S28: =O28*$B$23 -> 8.0124062 | T28: =ABS(R28-S28) -> 0.084981735 | U28: =ABS(S28-R28)/S28 -> 0.010606269 | V28: =$B$44*S28+$B$45 -> 0.21666667 | W28: =$B$46*R28+$B$47 -> 0.072575499 | X28: =ABS(V28-W28) -> 0.14409117 | Y28: =IF(V28 = 0, ABS(V28-W28)/(V28+0.0001), ABS(V28-W28)/V28) -> 0.66503616 | Z28: =ROUND((W28+5/3)/(1/12),6) -> 20.870906 | AA28: =ABS(G28-Z28)/G28 -> 0.076508584
A29: G_INA_add_Noise | B29: =$B$23-$B$23*$C$26 -> 3.6475653 | F29: 27 | G29: =F29*0.1+20 -> 22.7 | H29: =G29+273.15 -> 295.85 | I29: =ROUND(1/12*G29-5/3,6) -> 0.225 | J29: =ROUND(10000*EXP(($B$3)+($B$4/H29)+($B$5/(H29^2))+($B$6/(H29^3))),6) -> 11067.26 | K29: =$B$9*(2*$B$8+J29)-$B$9*$B$10 -> 10.08726 | L29: =ROUND(1/(1/(J29+2*$B$8)+1/($B$7)),6) -> 2171.251 | M29: 2169.43 | N29: =$B$9*(L29+$B$10)*(L29/(L29+$B$10)) -> 2.171251 | O29: =$B$11*G29+$B$12 -> 2.17017 | P29: =ABS(N29-O29) -> 0.001080977 | Q29: =ABS(O29-N29)/O29 -> 0.00049810706 | R29: =ROUND(N29*$B$29,6)+RANDBETWEEN(-1,1)*$B$24+RANDBETWEEN(-1,1)*$B$25 -> 7.9193839 | S29: =O29*$B$23 -> 8.0039603 | T29: =ABS(R29-S29) -> 0.08457646 | U29: =ABS(S29-R29)/S29 -> 0.010566826 | V29: =$B$44*S29+$B$45 -> 0.225 | W29: =$B$46*R29+$B$47 -> 0.080616137 | X29: =ABS(V29-W29) -> 0.14438386 | Y29: =IF(V29 = 0, ABS(V29-W29)/(V29+0.0001), ABS(V29-W29)/V29) -> 0.64170606 | Z29: =ROUND((W29+5/3)/(1/12),6) -> 20.967394 | AA29: =ABS(G29-Z29)/G29 -> 0.076326256
F30: 28 | G30: =F30*0.1+20 -> 22.8 | H30: =G30+273.15 -> 295.95 | I30: =ROUND(1/12*G30-5/3,6) -> 0.233333 | J30: =ROUND(10000*EXP(($B$3)+($B$4/H30)+($B$5/(H30^2))+($B$6/(H30^3))),6) -> 11018.268 | K30: =$B$9*(2*$B$8+J30)-$B$9*$B$10 -> 10.038268 | L30: =ROUND(1/(1/(J30+2*$B$8)+1/($B$7)),6) -> 2169.3654 | M30: 2167.43 | N30: =$B$9*(L30+$B$10)*(L30/(L30+$B$10)) -> 2.1693654 | O30: =$B$11*G30+$B$12 -> 2.16788 | P30: =ABS(N30-O30) -> 0.001485432 | Q30: =ABS(O30-N30)/O30 -> 0.00068520029 | R30: =ROUND(N30*$B$29,6)+RANDBETWEEN(-1,1)*$B$24+RANDBETWEEN(-1,1)*$B$25 -> 7.9128912 | S30: =O30*$B$23 -> 7.9955144 | T30: =ABS(R30-S30) -> 0.082623181 | U30: =ABS(S30-R30)/S30 -> 0.010333692 | V30: =$B$44*S30+$B$45 -> 0.23333333 | W30: =$B$46*R30+$B$47 -> 0.087108773 | X30: =ABS(V30-W30) -> 0.14622456 | Y30: =IF(V30 = 0, ABS(V30-W30)/(V30+0.0001), ABS(V30-W30)/V30) -> 0.62667669 | Z30: =ROUND((W30+5/3)/(1/12),6) -> 21.045305 | AA30: =ABS(G30-Z30)/G30 -> 0.076960307
A31: MAX_V_o_INA | B31: =MAX(R:R) -> 8.0999648 | C31: V | F31: 29 | G31: =F31*0.1+20 -> 22.9 | H31: =G31+273.15 -> 296.05 | I31: =ROUND(1/12*G31-5/3,6) -> 0.241667 | J31: =ROUND(10000*EXP(($B$3)+($B$4/H31)+($B$5/(H31^2))+($B$6/(H31^3))),6) -> 10969.522 | K31: =$B$9*(2*$B$8+J31)-$B$9*$B$10 -> 9.9895222 | L31: =ROUND(1/(1/(J31+2*$B$8)+1/($B$7)),6) -> 2167.4759 | M31: 2165.68 | N31: =$B$9*(L31+$B$10)*(L31/(L31+$B$10)) -> 2.1674759 | O31: =$B$11*G31+$B$12 -> 2.16559 | P31: =ABS(N31-O31) -> 0.001885935 | Q31: =ABS(O31-N31)/O31 -> 0.00087086429 | R31: =ROUND(N31*$B$29,6)+RANDBETWEEN(-1,1)*$B$24+RANDBETWEEN(-1,1)*$B$25 -> 7.9067915 | S31: =O31*$B$23 -> 7.9870685 | T31: =ABS(R31-S31) -> 0.080276993 | U31: =ABS(S31-R31)/S31 -> 0.010050871 | V31: =$B$44*S31+$B$45 -> 0.24166667 | W31: =$B$46*R31+$B$47 -> 0.093208499 | X31: =ABS(V31-W31) -> 0.14845817 | Y31: =IF(V31 = 0, ABS(V31-W31)/(V31+0.0001), ABS(V31-W31)/V31) -> 0.61430966 | Z31: =ROUND((W31+5/3)/(1/12),6) -> 21.118502 | AA31: =ABS(G31-Z31)/G31 -> 0.077794672
A32: MIN_V_o_INA | B32: =MIN(R:R) -> 3.1616991 | C32: V | F32: 30 | G32: =F32*0.1+20 -> 23 | H32: =G32+273.15 -> 296.15 | I32: =ROUND(1/12*G32-5/3,6) -> 0.25 | J32: =ROUND(10000*EXP(($B$3)+($B$4/H32)+($B$5/(H32^2))+($B$6/(H32^3))),6) -> 10921.02 | K32: =$B$9*(2*$B$8+J32)-$B$9*$B$10 -> 9.9410202 | L32: =ROUND(1/(1/(J32+2*$B$8)+1/($B$7)),6) -> 2165.5825 | M32: 2163.66 | N32: =$B$9*(L32+$B$10)*(L32/(L32+$B$10)) -> 2.1655825 | O32: =$B$11*G32+$B$12 -> 2.1633 | P32: =ABS(N32-O32) -> 0.002282495 | Q32: =ABS(O32-N32)/O32 -> 0.0010550987 | R32: =ROUND(N32*$B$29,6)+RANDBETWEEN(-1,1)*$B$24+RANDBETWEEN(-1,1)*$B$25 -> 7.8994884 | S32: =O32*$B$23 -> 7.9786226 | T32: =ABS(R32-S32) -> 0.079134216 | U32: =ABS(S32-R32)/S32 -> 0.0099182804 | V32: =$B$44*S32+$B$45 -> 0.25 | W32: =$B$46*R32+$B$47 -> 0.10051164 | X32: =ABS(V32-W32) -> 0.14948836 | Y32: =IF(V32 = 0, ABS(V32-W32)/(V32+0.0001), ABS(V32-W32)/V32) -> 0.59795346 | Z32: =ROUND((W32+5/3)/(1/12),6) -> 21.20614 | AA32: =ABS(G32-Z32)/G32 -> 0.077993913
A33: MAX_V_o_INA_ideal | B33: =MAX(S:S) -> 8.232 | C33: V | F33: 31 | G33: =F33*0.1+20 -> 23.1 | H33: =G33+273.15 -> 296.25 | I33: =ROUND(1/12*G33-5/3,6) -> 0.258333 | J33: =ROUND(10000*EXP(($B$3)+($B$4/H33)+($B$5/(H33^2))+($B$6/(H33^3))),6) -> 10872.761 | K33: =$B$9*(2*$B$8+J33)-$B$9*$B$10 -> 9.8927609 | L33: =ROUND(1/(1/(J33+2*$B$8)+1/($B$7)),6) -> 2163.6851 | M33: 2161.89 | N33: =$B$9*(L33+$B$10)*(L33/(L33+$B$10)) -> 2.1636851 | O33: =$B$11*G33+$B$12 -> 2.16101 | P33: =ABS(N33-O33) -> 0.002675115 | Q33: =ABS(O33-N33)/O33 -> 0.0012379003 | R33: =ROUND(N33*$B$29,6)+RANDBETWEEN(-1,1)*$B$24+RANDBETWEEN(-1,1)*$B$25 -> 7.8917869 | S33: =O33*$B$23 -> 7.9701767 | T33: =ABS(R33-S33) -> 0.078389804 | U33: =ABS(S33-R33)/S33 -> 0.009835391 | V33: =$B$44*S33+$B$45 -> 0.25833333 | W33: =$B$46*R33+$B$47 -> 0.10821314 | X33: =ABS(V33-W33) -> 0.1501202 | Y33: =IF(V33 = 0, ABS(V33-W33)/(V33+0.0001), ABS(V33-W33)/V33) -> 0.58111044 | Z33: =ROUND((W33+5/3)/(1/12),6) -> 21.298558 | AA33: =ABS(G33-Z33)/G33 -> 0.077984502
A34: MIN_V_o_INA_ideal | B34: =MIN(S:S) -> 3.1644516 | C34: V | F34: 32 | G34: =F34*0.1+20 -> 23.2 | H34: =G34+273.15 -> 296.35 | I34: =ROUND(1/12*G34-5/3,6) -> 0.266667 | J34: =ROUND(10000*EXP(($B$3)+($B$4/H34)+($B$5/(H34^2))+($B$6/(H34^3))),6) -> 10824.743 | K34: =$B$9*(2*$B$8+J34)-$B$9*$B$10 -> 9.8447429 | L34: =ROUND(1/(1/(J34+2*$B$8)+1/($B$7)),6) -> 2161.7838 | M34: 2159.86 | N34: =$B$9*(L34+$B$10)*(L34/(L34+$B$10)) -> 2.1617838 | O34: =$B$11*G34+$B$12 -> 2.15872 | P34: =ABS(N34-O34) -> 0.003063804 | Q34: =ABS(O34-N34)/O34 -> 0.0014192688 | R34: =ROUND(N34*$B$29,6)+RANDBETWEEN(-1,1)*$B$24+RANDBETWEEN(-1,1)*$B$25 -> 7.8848626 | S34: =O34*$B$23 -> 7.9617308 | T34: =ABS(R34-S34) -> 0.076868117 | U34: =ABS(S34-R34)/S34 -> 0.0096546994 | V34: =$B$44*S34+$B$45 -> 0.26666667 | W34: =$B$46*R34+$B$47 -> 0.11513736 | X34: =ABS(V34-W34) -> 0.1515293 | Y34: =IF(V34 = 0, ABS(V34-W34)/(V34+0.0001), ABS(V34-W34)/V34) -> 0.56823488 | Z34: =ROUND((W34+5/3)/(1/12),6) -> 21.381648 | AA34: =ABS(G34-Z34)/G34 -> 0.078377241
A35: MAX_Error_V_o_INA_ab | B35: =MAX(T:T) -> 0.13203523 | C35: V | F35: 33 | G35: =F35*0.1+20 -> 23.3 | H35: =G35+273.15 -> 296.45 | I35: =ROUND(1/12*G35-5/3,6) -> 0.275 | J35: =ROUND(10000*EXP(($B$3)+($B$4/H35)+($B$5/(H35^2))+($B$6/(H35^3))),6) -> 10776.965 | K35: =$B$9*(2*$B$8+J35)-$B$9*$B$10 -> 9.7969649 | L35: =ROUND(1/(1/(J35+2*$B$8)+1/($B$7)),6) -> 2159.8786 | M35: 2157.82 | N35: =$B$9*(L35+$B$10)*(L35/(L35+$B$10)) -> 2.1598786 | O35: =$B$11*G35+$B$12 -> 2.15643 | P35: =ABS(N35-O35) -> 0.003448567 | Q35: =ABS(O35-N35)/O35 -> 0.0015992019 | R35: =ROUND(N35*$B$29,6)+RANDBETWEEN(-1,1)*$B$24+RANDBETWEEN(-1,1)*$B$25 -> 7.8782872 | S35: =O35*$B$23 -> 7.9532848 | T35: =ABS(R35-S35) -> 0.074997611 | U35: =ABS(S35-R35)/S35 -> 0.0094297655 | V35: =$B$44*S35+$B$45 -> 0.275 | W35: =$B$46*R35+$B$47 -> 0.12171277 | X35: =ABS(V35-W35) -> 0.15328723 | Y35: =IF(V35 = 0, ABS(V35-W35)/(V35+0.0001), ABS(V35-W35)/V35) -> 0.5574081 | Z35: =ROUND((W35+5/3)/(1/12),6) -> 21.460553 | AA35: =ABS(G35-Z35)/G35 -> 0.078946223
A36: MIN_Error_V_o_INA_ab | B36: =MIN(T:T) -> 5.6451613e-05 | C36: V | F36: 34 | G36: =F36*0.1+20 -> 23.4 | H36: =G36+273.15 -> 296.55 | I36: =ROUND(1/12*G36-5/3,6) -> 0.283333 | J36: =ROUND(10000*EXP(($B$3)+($B$4/H36)+($B$5/(H36^2))+($B$6/(H36^3))),6) -> 10729.425 | K36: =$B$9*(2*$B$8+J36)-$B$9*$B$10 -> 9.7494255 | L36: =ROUND(1/(1/(J36+2*$B$8)+1/($B$7)),6) -> 2157.9694 | M36: 2156.03 | N36: =$B$9*(L36+$B$10)*(L36/(L36+$B$10)) -> 2.1579694 | O36: =$B$11*G36+$B$12 -> 2.15414 | P36: =ABS(N36-O36) -> 0.003829411 | Q36: =ABS(O36-N36)/O36 -> 0.0017776983 | R36: =ROUND(N36*$B$29,6)+RANDBETWEEN(-1,1)*$B$24+RANDBETWEEN(-1,1)*$B$25 -> 7.8721155 | S36: =O36*$B$23 -> 7.9448389 | T36: =ABS(R36-S36) -> 0.072723423 | U36: =ABS(S36-R36)/S36 -> 0.0091535428 | V36: =$B$44*S36+$B$45 -> 0.28333333 | W36: =$B$46*R36+$B$47 -> 0.1278845 | X36: =ABS(V36-W36) -> 0.15544883 | Y36: =IF(V36 = 0, ABS(V36-W36)/(V36+0.0001), ABS(V36-W36)/V36) -> 0.54864295 | Z36: =ROUND((W36+5/3)/(1/12),6) -> 21.534614 | AA36: =ABS(G36-Z36)/G36 -> 0.07971735
A37: MAX_Error_V_o_INA_re | B37: =MAX(U:U) -> 0.02721158 | C37: % | F37: 35 | G37: =F37*0.1+20 -> 23.5 | H37: =G37+273.15 -> 296.65 | I37: =ROUND(1/12*G37-5/3,6) -> 0.291667 | J37: =ROUND(10000*EXP(($B$3)+($B$4/H37)+($B$5/(H37^2))+($B$6/(H37^3))),6) -> 10682.123 | K37: =$B$9*(2*$B$8+J37)-$B$9*$B$10 -> 9.7021234 | L37: =ROUND(1/(1/(J37+2*$B$8)+1/($B$7)),6) -> 2156.0563 | M37: 2154.24 | N37: =$B$9*(L37+$B$10)*(L37/(L37+$B$10)) -> 2.1560563 | O37: =$B$11*G37+$B$12 -> 2.15185 | P37: =ABS(N37-O37) -> 0.004206343 | Q37: =ABS(O37-N37)/O37 -> 0.0019547566 | R37: =ROUND(N37*$B$29,6)+RANDBETWEEN(-1,1)*$B$24+RANDBETWEEN(-1,1)*$B$25 -> 7.8635745 | S37: =O37*$B$23 -> 7.936393 | T37: =ABS(R37-S37) -> 0.072818512 | U37: =ABS(S37-R37)/S37 -> 0.0091752654 | V37: =$B$44*S37+$B$45 -> 0.29166667 | W37: =$B$46*R37+$B$47 -> 0.1364255 | X37: =ABS(V37-W37) -> 0.15524117 | Y37: =IF(V37 = 0, ABS(V37-W37)/(V37+0.0001), ABS(V37-W37)/V37) -> 0.53225542 | Z37: =ROUND((W37+5/3)/(1/12),6) -> 21.637106 | AA37: =ABS(G37-Z37)/G37 -> 0.079272085
A38: MIN_Error_V_o_INA_re | B38: =MIN(U:U) -> 7.7389246e-06 | C38: % | F38: 36 | G38: =F38*0.1+20 -> 23.6 | H38: =G38+273.15 -> 296.75 | I38: =ROUND(1/12*G38-5/3,6) -> 0.3 | J38: =ROUND(10000*EXP(($B$3)+($B$4/H38)+($B$5/(H38^2))+($B$6/(H38^3))),6) -> 10635.057 | K38: =$B$9*(2*$B$8+J38)-$B$9*$B$10 -> 9.6550573 | L38: =ROUND(1/(1/(J38+2*$B$8)+1/($B$7)),6) -> 2154.1394 | M38: 2152.17 | N38: =$B$9*(L38+$B$10)*(L38/(L38+$B$10)) -> 2.1541394 | O38: =$B$11*G38+$B$12 -> 2.14956 | P38: =ABS(N38-O38) -> 0.004579369 | Q38: =ABS(O38-N38)/O38 -> 0.0021303751 | R38: =ROUND(N38*$B$29,6)+RANDBETWEEN(-1,1)*$B$24+RANDBETWEEN(-1,1)*$B$25 -> 7.8569679 | S38: =O38*$B$23 -> 7.9279471 | T38: =ABS(R38-S38) -> 0.070979234 | U38: =ABS(S38-R38)/S38 -> 0.0089530408 | V38: =$B$44*S38+$B$45 -> 0.3 | W38: =$B$46*R38+$B$47 -> 0.14303214 | X38: =ABS(V38-W38) -> 0.15696786 | Y38: =IF(V38 = 0, ABS(V38-W38)/(V38+0.0001), ABS(V38-W38)/V38) -> 0.52322621 | Z38: =ROUND((W38+5/3)/(1/12),6) -> 21.716386 | AA38: =ABS(G38-Z38)/G38 -> 0.079814153
F39: 37 | G39: =F39*0.1+20 -> 23.7 | H39: =G39+273.15 -> 296.85 | I39: =ROUND(1/12*G39-5/3,6) -> 0.308333 | J39: =ROUND(10000*EXP(($B$3)+($B$4/H39)+($B$5/(H39^2))+($B$6/(H39^3))),6) -> 10588.226 | K39: =$B$9*(2*$B$8+J39)-$B$9*$B$10 -> 9.6082259 | L39: =ROUND(1/(1/(J39+2*$B$8)+1/($B$7)),6) -> 2152.2185 | M39: 2150.11 | N39: =$B$9*(L39+$B$10)*(L39/(L39+$B$10)) -> 2.1522185 | O39: =$B$11*G39+$B$12 -> 2.14727 | P39: =ABS(N39-O39) -> 0.004948496 | Q39: =ABS(O39-N39)/O39 -> 0.0023045523 | R39: =ROUND(N39*$B$29,6)+RANDBETWEEN(-1,1)*$B$24+RANDBETWEEN(-1,1)*$B$25 -> 7.8507531 | S39: =O39*$B$23 -> 7.9195012 | T39: =ABS(R39-S39) -> 0.068748046 | U39: =ABS(S39-R39)/S39 -> 0.0086808555 | V39: =$B$44*S39+$B$45 -> 0.30833333 | W39: =$B$46*R39+$B$47 -> 0.14924686 | X39: =ABS(V39-W39) -> 0.15908647 | Y39: =IF(V39 = 0, ABS(V39-W39)/(V39+0.0001), ABS(V39-W39)/V39) -> 0.51595612 | Z39: =ROUND((W39+5/3)/(1/12),6) -> 21.790962 | AA39: =ABS(G39-Z39)/G39 -> 0.080550127
A40: Amplifier | F40: 38 | G40: =F40*0.1+20 -> 23.8 | H40: =G40+273.15 -> 296.95 | I40: =ROUND(1/12*G40-5/3,6) -> 0.316667 | J40: =ROUND(10000*EXP(($B$3)+($B$4/H40)+($B$5/(H40^2))+($B$6/(H40^3))),6) -> 10541.628 | K40: =$B$9*(2*$B$8+J40)-$B$9*$B$10 -> 9.5616279 | L40: =ROUND(1/(1/(J40+2*$B$8)+1/($B$7)),6) -> 2150.2937 | M40: 2148.29 | N40: =$B$9*(L40+$B$10)*(L40/(L40+$B$10)) -> 2.1502937 | O40: =$B$11*G40+$B$12 -> 2.14498 | P40: =ABS(N40-O40) -> 0.005313732 | Q40: =ABS(O40-N40)/O40 -> 0.0024772874 | R40: =ROUND(N40*$B$29,6)+RANDBETWEEN(-1,1)*$B$24+RANDBETWEEN(-1,1)*$B$25 -> 7.8429409 | S40: =O40*$B$23 -> 7.9110553 | T40: =ABS(R40-S40) -> 0.068114406 | U40: =ABS(S40-R40)/S40 -> 0.0086100278 | V40: =$B$44*S40+$B$45 -> 0.31666667 | W40: =$B$46*R40+$B$47 -> 0.15705914 | X40: =ABS(V40-W40) -> 0.15960753 | Y40: =IF(V40 = 0, ABS(V40-W40)/(V40+0.0001), ABS(V40-W40)/V40) -> 0.50402378 | Z40: =ROUND((W40+5/3)/(1/12),6) -> 21.88471 | AA40: =ABS(G40-Z40)/G40 -> 0.08047437
...

Sheet Cal_Error
A1: Point | B1: T_standard | C1: V_standard | E1: T_cal | F1: Error_Temperature | I1: Error_Voltage
A2: {=_xlfn.SEQUENCE(601,1,0,1)} -> 0 | B2: =0.1*A2+20 -> 20 | C2: =ROUND(1/12*B2-5/3,6) -> 0 | E2: =(ADC!I2+5/3)/(1/12) -> 20.275891 | F2: =ABS(B2-E2)/B2 -> 0.013794533 | G2: Max_E_T | H2: =MAX(F:F) -> 0.034167944 | I2: =ABS(C2-ADC!I2) -> 0.022990889 | J2: Max_E_V | K2: =MAX(I:I) -> 0.10217838
A3: 1 | B3: =0.1*A3+20 -> 20.1 | C3: =ROUND(1/12*B3-5/3,6) -> 0.008333 | E3: =(ADC!I3+5/3)/(1/12) -> 20.355421 | F3: =ABS(B3-E3)/B3 -> 0.012707498 | G3: Min_E_T | H3: =MIN(F:F) -> 4.1076467e-06 | I3: =ABS(C3-ADC!I3) -> 0.021285393 | J3: Min_E_V | K3: =MIN(I:I) -> 7.6244062e-06
A4: 2 | B4: =0.1*A4+20 -> 20.2 | C4: =ROUND(1/12*B4-5/3,6) -> 0.016667 | E4: =(ADC!I4+5/3)/(1/12) -> 20.423606 | F4: =ABS(B4-E4)/B4 -> 0.011069627 | I4: =ABS(C4-ADC!I4) -> 0.018633539
A5: 3 | B5: =0.1*A5+20 -> 20.3 | C5: =ROUND(1/12*B5-5/3,6) -> 0.025 | E5: =(ADC!I5+5/3)/(1/12) -> 20.503787 | F5: =ABS(B5-E5)/B5 -> 0.010038779 | I5: =ABS(C5-ADC!I5) -> 0.016982268
A6: 4 | B6: =0.1*A6+20 -> 20.4 | C6: =ROUND(1/12*B6-5/3,6) -> 0.033333 | E6: =(ADC!I6+5/3)/(1/12) -> 20.572643 | F6: =ABS(B6-E6)/B6 -> 0.0084628763 | I6: =ABS(C6-ADC!I6) -> 0.014387223
A7: 5 | B7: =0.1*A7+20 -> 20.5 | C7: =ROUND(1/12*B7-5/3,6) -> 0.041667 | E7: =(ADC!I7+5/3)/(1/12) -> 20.653474 | F7: =ABS(B7-E7)/B7 -> 0.0074865309 | I7: =ABS(C7-ADC!I7) -> 0.012789157
A8: 6 | B8: =0.1*A8+20 -> 20.6 | C8: =ROUND(1/12*B8-5/3,6) -> 0.05 | E8: =(ADC!I8+5/3)/(1/12) -> 20.734625 | F8: =ABS(B8-E8)/B8 -> 0.0065352141 | I8: =ABS(C8-ADC!I8) -> 0.011218784
A9: 7 | B9: =0.1*A9+20 -> 20.7 | C9: =ROUND(1/12*B9-5/3,6) -> 0.058333 | E9: =(ADC!I9+5/3)/(1/12) -> 20.816097 | F9: =ABS(B9-E9)/B9 -> 0.0056085585 | I9: =ABS(C9-ADC!I9) -> 0.0096750967
A10: 8 | B10: =0.1*A10+20 -> 20.8 | C10: =ROUND(1/12*B10-5/3,6) -> 0.066667 | E10: =(ADC!I10+5/3)/(1/12) -> 20.897889 | F10: =ABS(B10-E10)/B10 -> 0.0047062032 | I10: =ABS(C10-ADC!I10) -> 0.0081570855
A11: 9 | B11: =0.1*A11+20 -> 20.9 | C11: =ROUND(1/12*B11-5/3,6) -> 0.075 | E11: =(ADC!I11+5/3)/(1/12) -> 20.980001 | F11: =ABS(B11-E11)/B11 -> 0.0038277943 | I11: =ABS(C11-ADC!I11) -> 0.0066667417
A12: 10 | B12: =0.1*A12+20 -> 21 | C12: =ROUND(1/12*B12-5/3,6) -> 0.083333 | E12: =(ADC!I12+5/3)/(1/12) -> 21.062433 | F12: =ABS(B12-E12)/B12 -> 0.0029729844 | I12: =ABS(C12-ADC!I12) -> 0.005203056
A13: 11 | B13: =0.1*A13+20 -> 21.1 | C13: =ROUND(1/12*B13-5/3,6) -> 0.091667 | E13: =(ADC!I13+5/3)/(1/12) -> 21.133606 | F13: =ABS(B13-E13)/B13 -> 0.0015927054 | I13: =ABS(C13-ADC!I13) -> 0.0028001736
A14: 12 | B14: =0.1*A14+20 -> 21.2 | C14: =ROUND(1/12*B14-5/3,6) -> 0.1 | E14: =(ADC!I14+5/3)/(1/12) -> 21.216687 | F14: =ABS(B14-E14)/B14 -> 0.00078712362 | I14: =ABS(C14-ADC!I14) -> 0.0013905851
A15: 13 | B15: =0.1*A15+20 -> 21.3 | C15: =ROUND(1/12*B15-5/3,6) -> 0.108333 | E15: =(ADC!I15+5/3)/(1/12) -> 21.300087 | F15: =ABS(B15-E15)/B15 -> 4.1076467e-06 | I15: =ABS(C15-ADC!I15) -> 7.6244062e-06
... A602: 600 | B602: =0.1*A602+20 -> 80 | C602: =ROUND(1/12*B602-5/3,6) -> 5 | E602: =(ADC!I602+5/3)/(1/12) -> 80.1462 | F602: =ABS(B602-E602)/B602 -> 0.0018274948 | I602: =ABS(C602-ADC!I602) -> 0.012183299

Sheet ADC
H1: T_s | I1: V_i | J1: Offset_Vol | K1: Gain_Error | L1: G_E | M1: V_i_ADC | N1: Error_V_i_ADC | O1: D_out | P1: D_cal_error | Q1: BIN | R1: Cal_V | S1: Cal_Temp | T1: Error_re | V1: Error_ab
A2: Requirement | H2: 20 | I2: 0.022990889 | J2: =ROUND(H2*0.00000575 -0.00034,6) -> -0.000225 | K2: =ROUND(H2*0.000005-0.0001,6) -> 0 | L2: =ROUND(K2+($C$24*(H2-25)),6) -> -0.0015 | M2: =(I2-J2)/(1-L2)+$C$26+$D$27 -> 0.023239117 | N2: =ABS(I2-M2)/I2 -> 0.010796813 | O2: =ROUND((M2*(2^($C$12-1)))/$C$44,4) -> 123.9829 | P2: =ROUND(O2+$C$47+$C$49+RANDBETWEEN($B$45,$D$45),0) -> 125 | Q2: =_xlfn.BASE(IF(P2<0, P2+2^($C$12)-1, P2), 2, 16) -> 0000000001111101 | R2: =($C$16/2^($C$12-1)) * P2 -> 0.023436785 | S2: =(R2+5/3)/(1/12) -> 20.281241 | T2: =ABS(H2-S2)/H2 -> 0.014062071 | U2: =MAX(T:T) -> 0.033550466 | V2: =ROUND(ABS(H2-S2),6) -> 0.281241 | W2: =MAX(V:V) -> 1.911446
A3: ERROR | B3: 0.05 | H3: 20.1 | I3: 0.029618393 | J3: =ROUND(H3*0.00000575 -0.00034,6) -> -0.000224 | K3: =ROUND(H3*0.000005-0.0001,6) -> 1e-06 | L3: =ROUND(K3+($C$24*(H3-25)),6) -> -0.001469 | M3: =(I3-J3)/(1-L3)+$C$26+$D$27 -> 0.029856619 | N3: =ABS(I3-M3)/I3 -> 0.0080431719 | O3: =ROUND((M3*(2^($C$12-1)))/$C$44,4) -> 159.2879 | P3: =ROUND(O3+$C$47+$C$49+RANDBETWEEN($B$45,$D$45),0) -> 162 | Q3: =_xlfn.BASE(IF(P3<0, P3+2^($C$12)-1, P3), 2, 16) -> 0000000010100010 | R3: =($C$16/2^($C$12-1)) * P3 -> 0.030374073 | S3: =(R3+5/3)/(1/12) -> 20.364489 | T3: =ABS(H3-S3)/H3 -> 0.013158651 | U3: =MIN(T:T) -> 3.3469492e-05 | V3: =ROUND(ABS(H3-S3),6) -> 0.264489 | W3: =MIN(V:V) -> 0.001583
H4: 20.2 | I4: 0.035300539 | J4: =ROUND(H4*0.00000575 -0.00034,6) -> -0.000224 | K4: =ROUND(H4*0.000005-0.0001,6) -> 1e-06 | L4: =ROUND(K4+($C$24*(H4-25)),6) -> -0.001439 | M4: =(I4-J4)/(1-L4)+$C$26+$D$27 -> 0.035531493 | N4: =ABS(I4-M4)/I4 -> 0.0065424963 | O4: =ROUND((M4*(2^($C$12-1)))/$C$44,4) -> 189.5639 | P4: =ROUND(O4+$C$47+$C$49+RANDBETWEEN($B$45,$D$45),0) -> 188 | Q4: =_xlfn.BASE(IF(P4<0, P4+2^($C$12)-1, P4), 2, 16) -> 0000000010111100 | R4: =($C$16/2^($C$12-1)) * P4 -> 0.035248924 | S4: =(R4+5/3)/(1/12) -> 20.422987 | T4: =ABS(H4-S4)/H4 -> 0.011038965 | V4: =ROUND(ABS(H4-S4),6) -> 0.222987
H5: 20.3 | I5: 0.041982268 | J5: =ROUND(H5*0.00000575 -0.00034,6) -> -0.000223 | K5: =ROUND(H5*0.000005-0.0001,6) -> 2e-06 | L5: =ROUND(K5+($C$24*(H5-25)),6) -> -0.001408 | M5: =(I5-J5)/(1-L5)+$C$26+$D$27 -> 0.042203927 | N5: =ABS(I5-M5)/I5 -> 0.0052798133 | O5: =ROUND((M5*(2^($C$12-1)))/$C$44,4) -> 225.162 | P5: =ROUND(O5+$C$47+$C$49+RANDBETWEEN($B$45,$D$45),0) -> 223 | Q5: =_xlfn.BASE(IF(P5<0, P5+2^($C$12)-1, P5), 2, 16) -> 0000000011011111 | R5: =($C$16/2^($C$12-1)) * P5 -> 0.041811224 | S5: =(R5+5/3)/(1/12) -> 20.501735 | T5: =ABS(H5-S5)/H5 -> 0.0099376694 | V5: =ROUND(ABS(H5-S5),6) -> 0.201735
H6: 20.4 | I6: 0.047720223 | J6: =ROUND(H6*0.00000575 -0.00034,6) -> -0.000223 | K6: =ROUND(H6*0.000005-0.0001,6) -> 2e-06 | L6: =ROUND(K6+($C$24*(H6-25)),6) -> -0.001378 | M6: =(I6-J6)/(1-L6)+$C$26+$D$27 -> 0.047935248 | N6: =ABS(I6-M6)/I6 -> 0.0045059545 | O6: =ROUND((M6*(2^($C$12-1)))/$C$44,4) -> 255.7392 | P6: =ROUND(O6+$C$47+$C$49+RANDBETWEEN($B$45,$D$45),0) -> 254 | Q6: =_xlfn.BASE(IF(P6<0, P6+2^($C$12)-1, P6), 2, 16) -> 0000000011111110 | R6: =($C$16/2^($C$12-1)) * P6 -> 0.047623547 | S6: =(R6+5/3)/(1/12) -> 20.571483 | T6: =ABS(H6-S6)/H6 -> 0.0084060078 | V6: =ROUND(ABS(H6-S6),6) -> 0.171483
H7: 20.5 | I7: 0.054456157 | J7: =ROUND(H7*0.00000575 -0.00034,6) -> -0.000222 | K7: =ROUND(H7*0.000005-0.0001,6) -> 3e-06 | L7: =ROUND(K7+($C$24*(H7-25)),6) -> -0.001347 | M7: =(I7-J7)/(1-L7)+$C$26+$D$27 -> 0.054662605 | N7: =ABS(I7-M7)/I7 -> 0.0037910791 | O7: =ROUND((M7*(2^($C$12-1)))/$C$44,4) -> 291.6303 | P7: =ROUND(O7+$C$47+$C$49+RANDBETWEEN($B$45,$D$45),0) -> 295 | Q7: =_xlfn.BASE(IF(P7<0, P7+2^($C$12)-1, P7), 2, 16) -> 0000000100100111 | R7: =($C$16/2^($C$12-1)) * P7 -> 0.055310812 | S7: =(R7+5/3)/(1/12) -> 20.66373 | T7: =ABS(H7-S7)/H7 -> 0.0079868168 | V7: =ROUND(ABS(H7-S7),6) -> 0.16373
A8: ADC | H8: 20.6 | I8: 0.061218784 | J8: =ROUND(H8*0.00000575 -0.00034,6) -> -0.000222 | K8: =ROUND(H8*0.000005-0.0001,6) -> 3e-06 | L8: =ROUND(K8+($C$24*(H8-25)),6) -> -0.001317 | M8: =(I8-J8)/(1-L8)+$C$26+$D$27 -> 0.061417973 | N8: =ABS(I8-M8)/I8 -> 0.0032537222 | O8: =ROUND((M8*(2^($C$12-1)))/$C$44,4) -> 327.6708 | P8: =ROUND(O8+$C$47+$C$49+RANDBETWEEN($B$45,$D$45),0) -> 325 | Q8: =_xlfn.BASE(IF(P8<0, P8+2^($C$12)-1, P8), 2, 16) -> 0000000101000101 | R8: =($C$16/2^($C$12-1)) * P8 -> 0.06093564 | S8: =(R8+5/3)/(1/12) -> 20.731228 | T8: =ABS(H8-S8)/H8 -> 0.0063702759 | V8: =ROUND(ABS(H8-S8),6) -> 0.131228
B9: Min | C9: Typ | D9: Max | E9: Unit | H9: 20.7 | I9: 0.068008097 | J9: =ROUND(H9*0.00000575 -0.00034,6) -> -0.000221 | K9: =ROUND(H9*0.000005-0.0001,6) -> 4e-06 | L9: =ROUND(K9+($C$24*(H9-25)),6) -> -0.001286 | M9: =(I9-J9)/(1-L9)+$C$26+$D$27 -> 0.068199467 | N9: =ABS(I9-M9)/I9 -> 0.0028139307 | O9: =ROUND((M9*(2^($C$12-1)))/$C$44,4) -> 363.8507 | P9: =ROUND(O9+$C$47+$C$49+RANDBETWEEN($B$45,$D$45),0) -> 364 | Q9: =_xlfn.BASE(IF(P9<0, P9+2^($C$12)-1, P9), 2, 16) -> 0000000101101100 | R9: =($C$16/2^($C$12-1)) * P9 -> 0.068247917 | S9: =(R9+5/3)/(1/12) -> 20.818975 | T9: =ABS(H9-S9)/H9 -> 0.0057475848 | V9: =ROUND(ABS(H9-S9),6) -> 0.118975
A10: VDD | B10: 5.2 | C10: 5.5 | D10: 5.5 | E10: V | H10: 20.8 | I10: 0.074824086 | J10: =ROUND(H10*0.00000575 -0.00034,6) -> -0.00022 | K10: =ROUND(H10*0.000005-0.0001,6) -> 4e-06 | L10: =ROUND(K10+($C$24*(H10-25)),6) -> -0.001256 | M10: =(I10-J10)/(1-L10)+$C$26+$D$27 -> 0.075007948 | N10: =ABS(I10-M10)/I10 -> 0.0024572685 | O10: =ROUND((M10*(2^($C$12-1)))/$C$44,4) -> 400.1746 | P10: =ROUND(O10+$C$47+$C$49+RANDBETWEEN($B$45,$D$45),0) -> 398 | Q10: =_xlfn.BASE(IF(P10<0, P10+2^($C$12)-1, P10), 2, 16) -> 0000000110001110 | R10: =($C$16/2^($C$12-1)) * P10 -> 0.074622723 | S10: =(R10+5/3)/(1/12) -> 20.895473 | T10: =ABS(H10-S10)/H10 -> 0.0045900323 | V10: =ROUND(ABS(H10-S10),6) -> 0.095473
A11: GND | B11: -0.3 | C11: 0 | D11: 0.3 | E11: V | H11: 20.9 | I11: 0.081666742 | J11: =ROUND(H11*0.00000575 -0.00034,6) -> -0.00022 | K11: =ROUND(H11*0.000005-0.0001,6) -> 5e-06 | L11: =ROUND(K11+($C$24*(H11-25)),6) -> -0.001225 | M11: =(I11-J11)/(1-L11)+$C$26+$D$27 -> 0.081844553 | N11: =ABS(I11-M11)/I11 -> 0.0021772813 | O11: =ROUND((M11*(2^($C$12-1)))/$C$44,4) -> 436.6486 | P11: =ROUND(O11+$C$47+$C$49+RANDBETWEEN($B$45,$D$45),0) -> 440 | Q11: =_xlfn.BASE(IF(P11<0, P11+2^($C$12)-1, P11), 2, 16) -> 0000000110111000 | R11: =($C$16/2^($C$12-1)) * P11 -> 0.082497482 | S11: =(R11+5/3)/(1/12) -> 20.98997 | T11: =ABS(H11-S11)/H11 -> 0.0043047745 | V11: =ROUND(ABS(H11-S11),6) -> 0.08997
A12: Resolution | C12: 16 | E12: Bit | H12: 21 | I12: 0.088536056 | J12: =ROUND(H12*0.00000575 -0.00034,6) -> -0.000219 | K12: =ROUND(H12*0.000005-0.0001,6) -> 5e-06 | L12: =ROUND(K12+($C$24*(H12-25)),6) -> -0.001195 | M12: =(I12-J12)/(1-L12)+$C$26+$D$27 -> 0.08870712 | N12: =ABS(I12-M12)/I12 -> 0.0019321428 | O12: =ROUND((M12*(2^($C$12-1)))/$C$44,4) -> 473.261 | P12: =ROUND(O12+$C$47+$C$49+RANDBETWEEN($B$45,$D$45),0) -> 471 | Q12: =_xlfn.BASE(IF(P12<0, P12+2^($C$12)-1, P12), 2, 16) -> 0000000111010111 | R12: =($C$16/2^($C$12-1)) * P12 -> 0.088309805 | S12: =(R12+5/3)/(1/12) -> 21.059718 | T12: =ABS(H12-S12)/H12 -> 0.002843698 | V12: =ROUND(ABS(H12-S12),6) -> 0.059718
A13: Analog_In_V_to_GND | E13: V | H13: 21.1 | I13: 0.094467174 | J13: =ROUND(H13*0.00000575 -0.00034,6) -> -0.000219 | K13: =ROUND(H13*0.000005-0.0001,6) -> 6e-06 | L13: =ROUND(K13+($C$24*(H13-25)),6) -> -0.001164 | M13: =(I13-J13)/(1-L13)+$C$26+$D$27 -> 0.094634087 | N13: =ABS(I13-M13)/I13 -> 0.0017668935 | O13: =ROUND((M13*(2^($C$12-1)))/$C$44,4) -> 504.882 | P13: =ROUND(O13+$C$47+$C$49+RANDBETWEEN($B$45,$D$45),0) -> 508 | Q13: =_xlfn.BASE(IF(P13<0, P13+2^($C$12)-1, P13), 2, 16) -> 0000000111111100 | R13: =($C$16/2^($C$12-1)) * P13 -> 0.095247093 | S13: =(R13+5/3)/(1/12) -> 21.142965 | T13: =ABS(H13-S13)/H13 -> 0.0020362615 | V13: =ROUND(ABS(H13-S13),6) -> 0.042965
A14: Temperature | B14: -60 | D14: 150 | E14: độ C | H14: 21.2 | I14: 0.10139059 | J14: =ROUND(H14*0.00000575 -0.00034,6) -> -0.000218 | K14: =ROUND(H14*0.000005-0.0001,6) -> 6e-06 | L14: =ROUND(K14+($C$24*(H14-25)),6) -> -0.001134 | M14: =(I14-J14)/(1-L14)+$C$26+$D$27 -> 0.10155149 | N14: =ABS(I14-M14)/I14 -> 0.0015869953 | O14: =ROUND((M14*(2^($C$12-1)))/$C$44,4) -> 541.787 | P14: =ROUND(O14+$C$47+$C$49+RANDBETWEEN($B$45,$D$45) + 1,0) -> 546 | Q14: =_xlfn.BASE(IF(P14<0, P14+2^($C$12)-1, P14), 2, 16) -> 0000001000100010 | R14: =($C$16/2^($C$12-1)) * P14 -> 0.10237188 | S14: =(R14+5/3)/(1/12) -> 21.228463 | T14: =ABS(H14-S14)/H14 -> 0.0013425712 | V14: =ROUND(ABS(H14-S14),6) -> 0.028463
A15: PGA (program gain amplifier) | B15: =2/3 -> 0.66666667 | C15: =2/3*$C$24+$B$15 -> 0.66686667 | H15: 21.3 | I15: 0.10834062 | J15: =ROUND(H15*0.00000575 -0.00034,6) -> -0.000218 | K15: =ROUND(H15*0.000005-0.0001,6) -> 7e-06 | L15: =ROUND(K15+($C$24*(H15-25)),6) -> -0.001103 | M15: =(I15-J15)/(1-L15)+$C$26+$D$27 -> 0.10849702 | N15: =ABS(I15-M15)/I15 -> 0.0014435191 | O15: =ROUND((M15*(2^($C$12-1)))/$C$44,4) -> 578.842 | P15: =ROUND(O15+$C$47+$C$49+RANDBETWEEN($B$45,$D$45) + 1,0) -> 579 | Q15: =_xlfn.BASE(IF(P15<0, P15+2^($C$12)-1, P15), 2, 16) -> 0000001001000011 | R15: =($C$16/2^($C$12-1)) * P15 -> 0.10855919 | S15: =(R15+5/3)/(1/12) -> 21.30271 | T15: =ABS(H15-S15)/H15 -> 0.00012724147 | V15: =ROUND(ABS(H15-S15),6) -> 0.00271
A16: FS (Full-Scale) | B16: =-4.096/$C$15 -> -6.1421574 | C16: =4.096/$B$15 * ((2^15 - 1)/(2^15)) -> 6.1438125 | D16: =4.096/$C$15 -> 6.1421574 | E16: V | H16: 21.4 | I16: 0.11531728 | J16: =ROUND(H16*0.00000575 -0.00034,6) -> -0.000217 | K16: =ROUND(H16*0.000005-0.0001,6) -> 7e-06 | L16: =ROUND(K16+($C$24*(H16-25)),6) -> -0.001073 | M16: =(I16-J16)/(1-L16)+$C$26+$D$27 -> 0.11546845 | N16: =ABS(I16-M16)/I16 -> 0.0013108581 | O16: =ROUND((M16*(2^($C$12-1)))/$C$44,4) -> 616.0353 | P16: =ROUND(O16+$C$47+$C$49+RANDBETWEEN($B$45,$D$45) + 1,0) -> 620 | Q16: =_xlfn.BASE(IF(P16<0, P16+2^($C$12)-1, P16), 2, 16) -> 0000001001101100 | R16: =($C$16/2^($C$12-1)) * P16 -> 0.11624645 | S16: =(R16+5/3)/(1/12) -> 21.394957 | T16: =ABS(H16-S16)/H16 -> 0.00023563421 | V16: =ROUND(ABS(H16-S16),6) -> 0.005043
A17: Common-Mode Input Impedance | C17: =6000000 -> 6000000 | E17: Ohm | H17: 21.5 | I17: 0.12232054 | J17: =ROUND(H17*0.00000575 -0.00034,6) -> -0.000216 | K17: =ROUND(H17*0.000005-0.0001,6) -> 8e-06 | L17: =ROUND(K17+($C$24*(H17-25)),6) -> -0.001042 | M17: =(I17-J17)/(1-L17)+$C$26+$D$27 -> 0.12246699 | N17: =ABS(I17-M17)/I17 -> 0.0011972628 | O17: =ROUND((M17*(2^($C$12-1)))/$C$44,4) -> 653.3732 | P17: =ROUND(O17+$C$47+$C$49+RANDBETWEEN($B$45,$D$45) + 1,0) -> 654 | Q17: =_xlfn.BASE(IF(P17<0, P17+2^($C$12)-1, P17), 2, 16) -> 0000001010001110 | R17: =($C$16/2^($C$12-1)) * P17 -> 0.12262126 | S17: =(R17+5/3)/(1/12) -> 21.471455 | T17: =ABS(H17-S17)/H17 -> 0.0013276701 | V17: =ROUND(ABS(H17-S17),6) -> 0.028545
A18: DR (Data Rate) | C18: 128 | E18: SPS | H18: 21.6 | I18: 0.12838963 | J18: =ROUND(H18*0.00000575 -0.00034,6) -> -0.000216 | K18: =ROUND(H18*0.000005-0.0001,6) -> 8e-06 | L18: =ROUND(K18+($C$24*(H18-25)),6) -> -0.001012 | M18: =(I18-J18)/(1-L18)+$C$26+$D$27 -> 0.12853361 | N18: =ABS(I18-M18)/I18 -> 0.001121451 | O18: =ROUND((M18*(2^($C$12-1)))/$C$44,4) -> 685.7392 | P18: =ROUND(O18+$C$47+$C$49+RANDBETWEEN($B$45,$D$45) + 1,0) -> 684 | Q18: =_xlfn.BASE(IF(P18<0, P18+2^($C$12)-1, P18), 2, 16) -> 0000001010101100 | R18: =($C$16/2^($C$12-1)) * P18 -> 0.12824609 | S18: =(R18+5/3)/(1/12) -> 21.538953 | T18: =ABS(H18-S18)/H18 -> 0.0028262485 | V18: =ROUND(ABS(H18-S18),6) -> 0.061047
A19: Range_Temperature | B19: 20 | D19: 80 | E19: độ C | H19: 21.7 | I19: 0.13544689 | J19: =ROUND(H19*0.00000575 -0.00034,6) -> -0.000215 | K19: =ROUND(H19*0.000005-0.0001,6) -> 9e-06 | L19: =ROUND(K19+($C$24*(H19-25)),6) -> -0.000981 | M19: =(I19-J19)/(1-L19)+$C$26+$D$27 -> 0.13558693 | N19: =ABS(I19-M19)/I19 -> 0.001033956 | O19: =ROUND((M19*(2^($C$12-1)))/$C$44,4) -> 723.3693 | P19: =ROUND(O19+$C$47+$C$49+RANDBETWEEN($B$45,$D$45) + 1,0) -> 728 | Q19: =_xlfn.BASE(IF(P19<0, P19+2^($C$12)-1, P19), 2, 16) -> 0000001011011000 | R19: =($C$16/2^($C$12-1)) * P19 -> 0.13649583 | S19: =(R19+5/3)/(1/12) -> 21.63795 | T19: =ABS(H19-S19)/H19 -> 0.0028594464 | V19: =ROUND(ABS(H19-S19),6) -> 0.06205
A20: Offset Voltage | B20: =-0.000225 -> -0.000225 | D20: =-0.00012 -> -0.00012 | E20: V | H20: 21.8 | I20: 0.14253071 | J20: =ROUND(H20*0.00000575 -0.00034,6) -> -0.000215 | K20: =ROUND(H20*0.000005-0.0001,6) -> 9e-06 | L20: =ROUND(K20+($C$24*(H20-25)),6) -> -0.000951 | M20: =(I20-J20)/(1-L20)+$C$26+$D$27 -> 0.14266808 | N20: =ABS(I20-M20)/I20 -> 0.00096384711 | O20: =ROUND((M20*(2^($C$12-1)))/$C$44,4) -> 761.1479 | P20: =ROUND(O20+$C$47+$C$49+RANDBETWEEN($B$45,$D$45) + 1,0) -> 761 | Q20: =_xlfn.BASE(IF(P20<0, P20+2^($C$12)-1, P20), 2, 16) -> 0000001011111001 | R20: =($C$16/2^($C$12-1)) * P20 -> 0.14268315 | S20: =(R20+5/3)/(1/12) -> 21.712198 | T20: =ABS(H20-S20)/H20 -> 0.0040276263 | V20: =ROUND(ABS(H20-S20),6) -> 0.087802
H21: 21.9 | I21: 0.14964108 | J21: =ROUND(H21*0.00000575 -0.00034,6) -> -0.000214 | K21: =ROUND(H21*0.000005-0.0001,6) -> 1e-05 | L21: =ROUND(K21+($C$24*(H21-25)),6) -> -0.00092 | M21: =(I21-J21)/(1-L21)+$C$26+$D$27 -> 0.14977534 | N21: =ABS(I21-M21)/I21 -> 0.0008972138 | O21: =ROUND((M21*(2^($C$12-1)))/$C$44,4) -> 799.0659 | P21: =ROUND(O21+$C$47+$C$49+RANDBETWEEN($B$45,$D$45) + 1,0) -> 801 | Q21: =_xlfn.BASE(IF(P21<0, P21+2^($C$12)-1, P21), 2, 16) -> 0000001100100001 | R21: =($C$16/2^($C$12-1)) * P21 -> 0.15018292 | S21: =(R21+5/3)/(1/12) -> 21.802195 | T21: =ABS(H21-S21)/H21 -> 0.0044659817 | V21: =ROUND(ABS(H21-S21),6) -> 0.097805
A22: Gain Error | B22: 0 | D22: 0.0003 | E22: % | H22: 22 | I22: 0.15582053 | J22: =ROUND(H22*0.00000575 -0.00034,6) -> -0.000214 | K22: =ROUND(H22*0.000005-0.0001,6) -> 1e-05 | L22: =ROUND(K22+($C$24*(H22-25)),6) -> -0.00089 | M22: =(I22-J22)/(1-L22)+$C$26+$D$27 -> 0.15595378 | N22: =ABS(I22-M22)/I22 -> 0.00085516813 | O22: =ROUND((M22*(2^($C$12-1)))/$C$44,4) -> 832.0284 | P22: =ROUND(O22+$C$47+$C$49+RANDBETWEEN($B$45,$D$45) + 1,0) -> 834 | Q22: =_xlfn.BASE(IF(P22<0, P22+2^($C$12)-1, P22), 2, 16) -> 0000001101000010 | R22: =($C$16/2^($C$12-1)) * P22 -> 0.15637023 | S22: =(R22+5/3)/(1/12) -> 21.876443 | T22: =ABS(H22-S22)/H22 -> 0.0056162394 | V22: =ROUND(ABS(H22-S22),6) -> 0.123557
A23: Gain Drift | C23: 5e-06 | E23: %/độ C | H23: 22.1 | I23: 0.1629848 | J23: =ROUND(H23*0.00000575 -0.00034,6) -> -0.000213 | K23: =ROUND(H23*0.000005-0.0001,6) -> 1.1e-05 | L23: =ROUND(K23+($C$24*(H23-25)),6) -> -0.000859 | M23: =(I23-J23)/(1-L23)+$C$26+$D$27 -> 0.16311573 | N23: =ABS(I23-M23)/I23 -> 0.00080334735 | O23: =ROUND((M23*(2^($C$12-1)))/$C$44,4) -> 870.2381 | P23: =ROUND(O23+$C$47+$C$49+RANDBETWEEN($B$45,$D$45) + 1,0) -> 870 | Q23: =_xlfn.BASE(IF(P23<0, P23+2^($C$12)-1, P23), 2, 16) -> 0000001101100110 | R23: =($C$16/2^($C$12-1)) * P23 -> 0.16312002 | S23: =(R23+5/3)/(1/12) -> 21.95744 | T23: =ABS(H23-S23)/H23 -> 0.0064506669 | V23: =ROUND(ABS(H23-S23),6) -> 0.14256
B24: Tại FS = 6.144 | C24: =($D$19-$B$19)*C23 -> 0.0003 | H24: 22.2 | I24: 0.17017558 | J24: =ROUND(H24*0.00000575 -0.00034,6) -> -0.000212 | K24: =ROUND(H24*0.000005-0.0001,6) -> 1.1e-05 | L24: =ROUND(K24+($C$24*(H24-25)),6) -> -0.000829 | M24: =(I24-J24)/(1-L24)+$C$26+$D$27 -> 0.17030445 | N24: =ABS(I24-M24)/I24 -> 0.00075725141 | O24: =ROUND((M24*(2^($C$12-1)))/$C$44,4) -> 908.5906 | P24: =ROUND(O24+$C$47+$C$49+RANDBETWEEN($B$45,$D$45) + 1,0) -> 912 | Q24: =_xlfn.BASE(IF(P24<0, P24+2^($C$12)-1, P24), 2, 16) -> 0000001110010000 | R24: =($C$16/2^($C$12-1)) * P24 -> 0.17099478 | S24: =(R24+5/3)/(1/12) -> 22.051937 | T24: =ABS(H24-S24)/H24 -> 0.0066694875 | V24: =ROUND(ABS(H24-S24),6) -> 0.148063
A25: Common Mode Rejection | B25: Tại FS = 6.144 | C25: 90 | E25: dB | H25: 22.3 | I25: 0.17643788 | J25: =ROUND(H25*0.00000575 -0.00034,6) -> -0.000212 | K25: =ROUND(H25*0.000005-0.0001,6) -> 1.2e-05 | L25: =ROUND(K25+($C$24*(H25-25)),6) -> -0.000798 | M25: =(I25-J25)/(1-L25)+$C$26+$D$27 -> 0.17656703 | N25: =ABS(I25-M25)/I25 -> 0.00073196185 | O25: =ROUND((M25*(2^($C$12-1)))/$C$44,4) -> 942.0021 | P25: =ROUND(O25+$C$47+$C$49+RANDBETWEEN($B$45,$D$45) + 1,0) -> 943 | Q25: =_xlfn.BASE(IF(P25<0, P25+2^($C$12)-1, P25), 2, 16) -> 0000001110101111 | R25: =($C$16/2^($C$12-1)) * P25 -> 0.1768071 | S25: =(R25+5/3)/(1/12) -> 22.121685 | T25: =ABS(H25-S25)/H25 -> 0.0079961772 | V25: =ROUND(ABS(H25-S25),6) -> 0.178315
A26: INL _vs_VoltageSupply | C26: =0.00002 -> 2e-05 | E26: V | H26: 22.4 | I26: 0.18368247 | J26: =ROUND(H26*0.00000575 -0.00034,6) -> -0.000211 | K26: =ROUND(H26*0.000005-0.0001,6) -> 1.2e-05 | L26: =ROUND(K26+($C$24*(H26-25)),6) -> -0.000768 | M26: =(I26-J26)/(1-L26)+$C$26+$D$27 -> 0.18381035 | N26: =ABS(I26-M26)/I26 -> 0.00069619164 | O26: =ROUND((M26*(2^($C$12-1)))/$C$44,4) -> 980.6459 | P26: =ROUND(O26+$C$47+$C$49+RANDBETWEEN($B$45,$D$45) + 1,0) -> 981 | Q26: =_xlfn.BASE(IF(P26<0, P26+2^($C$12)-1, P26), 2, 16) -> 0000001111010101 | R26: =($C$16/2^($C$12-1)) * P26 -> 0.18393189 | S26: =(R26+5/3)/(1/12) -> 22.207183 | T26: =ABS(H26-S26)/H26 -> 0.0086079179 | V26: =ROUND(ABS(H26-S26),6) -> 0.192817
